Workbook

Sheet 计算模型
A1: 事故源项计算模型
A2: 空间 释放机制 | B2: 产生 | C2: 转移 | D2: 去除
A3: 燃料A(t) | B3: 裂变、活化 | C3: 燃料释放rA(t) | D3: 衰变λA(t)
A4: 一回路B(t) | B4: 燃料释放rA(t) | C4: 一回路释放fB(t) | D4: 衰变λB(t)，过滤，沉积
A5: 舱室/安全壳C(t) | B5: 一回路释放fB(t) | C5: 安全壳释放wC(t) | D5: 衰变λC(t)，过滤，沉积
A6: 环境D(t) | B6: 安全壳释放wC(t) | C6: 无 | D6: 衰变λD(t)
A9: 关键参数说明
A10: 燃料释放率r | B10: 根据燃料温度分布，由扩散计算获得燃料向一回路释放率
A11: 一回路释放率f | B11: 根据一回路破口或开阀泄压、堆芯升温和核素扩散等综合作用计算一回路向安全壳释放率： （1）泄压过程：由泄压比例和时长确定释放率； （2）堆芯升温：压力平衡后，堆芯升温阶段，根据温度提升比例确定释放率； （3）核素扩散：压力平衡后，堆芯不再升温，假设1%核素扩散释放到安全壳。 若破口成功隔离或安全阀关闭，一回路停止释放，释放率为0；若发生大破口或爆破快速泄压，发生瞬时释放。
A12: 舱室/安全壳释放率w | B12: 根据舱室/安全壳名义泄漏率确定安全壳向环境释放率，如100%Vol/d或10%Vol/d；若安全壳发生爆破，与环境连通，释放率取无穷大
A13: 过滤 | B13: 通常不考虑，除非明确净化系统或碘过滤器正常运行，则根据过滤效率确定
A14: 沉积 | B14: 不考虑其他沉积、去除作用
A16: 初值确定
A17: 初值由正常源项确定，包括堆芯总量（燃料）、一回路源项、安全壳源项等，根据一回路破口或开阀确定释放初始时刻，考虑事故后至初始时刻期间的释放作用
A23: 本工程安全壳泄漏率 | B23: 1 | C23: vol/d
A24: 核素扩散 | B24: 0.01

Sheet 正常源项
A1: 核素 | B1: 衰变常数λ | C1: 堆芯总量,bq | D1: 正常 | E1: 倍数 | F1: 正常工况安全壳内剂量 | G1: 正常 | H1: 倍数 | I1: 冷却剂中稳态平衡量,bq | J1: 正常 | K1: 倍数 | L1: 氦净化系统低温吸附器和分子筛上的量 | M1: 正常 | N1: 倍数 | O1: 一回路表面沉积量 | P1: 正常 | Q1: 倍数 | R1: 尘埃过滤器总 | S1: 氧化铜床总
A2: Kr-83m | B2: =VLOOKUP(A2,衰变常数!$A$1:$H$3800,7,FALSE) -> 0.0001052136 | C2: 2.35e+16 | D2: 2.11e+16 | E2: =C2/D2 -> 1.1137441 | G2: 18316616 | H2: =F2/G2 -> 0 | I2: 4250000000 | J2: 5400000000 | K2: =I2/J2 -> 0.78703704 | L2: 179000000 | M2: 227000000 | N2: =L2/M2 -> 0.78854626 | R2: 6026574.4 | S2: 39507825
A3: Kr-85 | B3: =VLOOKUP(A3,衰变常数!$A$1:$H$3800,7,FALSE) -> 2.0420706e-09 | C3: 1.86e+15 | D3: 2.1e+15 | E3: =C3/D3 -> 0.88571429 | G3: 21561996 | H3: =F3/G3 -> 0 | I3: 46200000 | J3: 73000000 | K3: =I3/J3 -> 0.63287671 | L3: 1030000000 | M3: 1630000000 | N3: =L3/M3 -> 0.63190184 | R3: 44071.482 | S3: 293809.79
A4: Kr-85m | B4: =VLOOKUP(A4,衰变常数!$A$1:$H$3800,7,FALSE) -> 4.2977876e-05 | C4: 6.59e+16 | D4: 6.18e+16 | E4: =C4/D4 -> 1.066343 | G4: 1.8871881e+08 | H4: =F4/G4 -> 0 | I4: 17900000000 | J4: 24000000000 | K4: =I4/J4 -> 0.74583333 | L4: 1580000000 | M4: 2110000000 | N4: =L4/M4 -> 0.74881517 | R4: 24396956 | S4: 1.6153121e+08
A5: Kr-87 | B5: =VLOOKUP(A5,衰变常数!$A$1:$H$3800,7,FALSE) -> 0.0001514083 | C5: 1.29e+17 | D5: 1.2e+17 | E5: =C5/D5 -> 1.075 | G5: 60363986 | H5: =F5/G5 -> 0 | I5: 19400000000 | J5: 27000000000 | K5: =I5/J5 -> 0.71851852 | L5: 567000000 | M5: 787000000 | N5: =L5/M5 -> 0.72045743 | R5: 26576418 | S5: 1.7289151e+08
A6: Kr-88 | B6: =VLOOKUP(A6,衰变常数!$A$1:$H$3800,7,FALSE) -> 6.7796086e-05 | C6: 1.88e+17 | D6: 1.75e+17 | E6: =C6/D6 -> 1.0742857 | G6: 2.779469e+08 | H6: =F6/G6 -> 0 | I6: 41500000000 | J6: 55000000000 | K6: =I6/J6 -> 0.75454545 | L6: 2390000000 | M6: 3160000000 | N6: =L6/M6 -> 0.75632911 | R6: 56447944 | S6: 3.7219982e+08
A7: Xe-131m | B7: =VLOOKUP(A7,衰变常数!$A$1:$H$3800,7,FALSE) -> 6.7757912e-07 | C7: 2.5e+15 | D7: 2.9e+15 | E7: =C7/D7 -> 0.86206897 | G7: 3.1178391e+08 | H7: =F7/G7 -> 0 | I7: 939000000 | J7: 1600000000 | K7: =I7/J7 -> 0.586875 | L7: 4820000000 | M7: 8210000000 | N7: =L7/M7 -> 0.58708892 | R7: 1071543.5 | S7: 7142858.7
A8: Xe-133 | B8: =VLOOKUP(A8,衰变常数!$A$1:$H$3800,7,FALSE) -> 1.5301424e-06 | C8: 4.58e+17 | D8: 5.33e+17 | E8: =C8/D8 -> 0.85928705 | G8: 4.3929162e+10 | H8: =F8/G8 -> 0 | I8: 216000000000 | J8: 340000000000 | K8: =I8/J8 -> 0.63529412 | L8: 492000000000 | M8: 775000000000 | N8: =L8/M8 -> 0.63483871 | R8: 2.695684e+08 | S8: 1.7966828e+09
A9: Xe-133m | B9: =VLOOKUP(A9,衰变常数!$A$1:$H$3800,7,FALSE) -> 3.6632588e-06 | C9: 1.32e+16 | D9: 1.43e+16 | E9: =C9/D9 -> 0.92307692 | G9: 8.0893683e+08 | H9: =F9/G9 -> 0 | I9: 6770000000 | J9: 11000000000 | K9: =I9/J9 -> 0.61545455 | L9: 6490000000 | M9: 10600000000 | N9: =L9/M9 -> 0.61226415 | R9: 8535811.7 | S9: 56872188
A10: Xe-135 | B10: =VLOOKUP(A10,衰变常数!$A$1:$H$3800,7,FALSE) -> 2.1065742e-05 | C10: 1.06e+17 | D10: 1.11e+17 | E10: =C10/D10 -> 0.95495495 | G10: 8.0758718e+08 | H10: =F10/G10 -> 0 | I10: 37900000000 | J10: 51000000000 | K10: =I10/J10 -> 0.74313725 | L10: 6490000000 | M10: 8730000000 | N10: =L10/M10 -> 0.74341352 | R10: 69788278 | S10: 4.6367971e+08
A11: I-131 | B11: =VLOOKUP(A11,衰变常数!$A$1:$H$3800,7,FALSE) -> 9.9966812e-07 | C11: 2.27e+17 | D11: 2.73e+17 | E11: =C11/D11 -> 0.83150183 | G11: 17406179 | H11: =F11/G11 -> 0 | I11: 19600000 | J11: 110000000 | K11: =I11/J11 -> 0.17818182 | O11: 435000000000 | P11: 720000000000 | Q11: =O11/P11 -> 0.60416667 | R11: 1.3626085e+09
A12: I-132 | B12: =VLOOKUP(A12,衰变常数!$A$1:$H$3800,7,FALSE) -> 8.389581e-05 | C12: 3.35e+17 | D12: 3.69e+17 | E12: =C12/D12 -> 0.90785908 | G12: 5728564.3 | H12: =F12/G12 -> 0 | I12: 261000000 | J12: 1400000000 | K12: =I12/J12 -> 0.18642857 | O12: 69400000000 | P12: 120000000000 | Q12: =O12/P12 -> 0.57833333 | R12: 2.2016561e+08
A13: I-133 | B13: =VLOOKUP(A13,衰变常数!$A$1:$H$3800,7,FALSE) -> 9.2567732e-06 | C13: 4.55e+17 | D13: 4.56e+17 | E13: =C13/D13 -> 0.99780702 | G13: 18665339 | H13: =F13/G13 -> 0 | I13: 119000000 | J13: 570000000 | K13: =I13/J13 -> 0.20877193 | O13: 286000000000 | P13: 400000000000 | Q13: =O13/P13 -> 0.715 | R13: 9.4134336e+08
A14: I-134 | B14: =VLOOKUP(A14,衰变常数!$A$1:$H$3800,7,FALSE) -> 0.00022004672 | C14: 5.26e+17 | D14: 5.22e+17 | E14: =C14/D14 -> 1.0076628 | G14: 4772870 | H14: =F14/G14 -> 0 | I14: 653000000 | J14: 3000000000 | K14: =I14/J14 -> 0.21766667 | O14: 66500000000 | P14: 95000000000 | Q14: =O14/P14 -> 0.7 | R14: 2.1441551e+08
A15: I-135 | B15: =VLOOKUP(A15,衰变常数!$A$1:$H$3800,7,FALSE) -> 2.9306071e-05 | C15: 3.77e+17 | D15: 3.8e+17 | E15: =C15/D15 -> 0.99210526 | G15: 9768653.5 | H15: =F15/G15 -> 0 | I15: 173000000 | J15: 840000000 | K15: =I15/J15 -> 0.20595238 | O15: 134000000000 | P15: 180000000000 | Q15: =O15/P15 -> 0.74444444 | R15: 4.4155917e+08
A16: Sr-89 | B16: =VLOOKUP(A16,衰变常数!$A$1:$H$3800,7,FALSE) -> 1.587678e-07 | C16: 2.39e+17 | D16: 2.51e+17 | E16: =C16/D16 -> 0.95219124 | G16: 6963.3964 | H16: =F16/G16 -> 0 | I16: 2860 | J16: 26000 | K16: =I16/J16 -> 0.11 | O16: 5990000000 | P16: 21000000000 | Q16: =O16/P16 -> 0.2852381 | R16: 930899.2
A17: Sr-90 | B17: =VLOOKUP(A17,衰变常数!$A$1:$H$3800,7,FALSE) -> 7.6292146e-10 | C17: 1.12e+16 | D17: 1.25e+16 | E17: =C17/D17 -> 0.896 | G17: 51.56516 | H17: =F17/G17 -> 0 | I17: 39.4 | J17: 170 | K17: =I17/J17 -> 0.23176471 | O17: 1790000000 | P17: 3300000000 | Q17: =O17/P17 -> 0.54242424 | R17: 311901.38
A18: Cs-134 | B18: =VLOOKUP(A18,衰变常数!$A$1:$H$3800,7,FALSE) -> 1.0635535e-08 | C18: 1.46e+16 | D18: 1.53e+16 | E18: =C18/D18 -> 0.95424837 | G18: 45186.167 | H18: =F18/G18 -> 0 | I18: 385000 | J18: 150000 | K18: =I18/J18 -> 2.5666667 | O18: 806000000000 | P18: 230000000000 | Q18: =O18/P18 -> 3.5043478 | R18: 87961201
A19: Cs-137 | B19: =VLOOKUP(A19,衰变常数!$A$1:$H$3800,7,FALSE) -> 7.3020309e-10 | C19: 1.74e+16 | D19: 1.91e+16 | E19: =C19/D19 -> 0.91099476 | G19: 58762.988 | H19: =F19/G19 -> 0 | I19: 544000 | J19: 250000 | K19: =I19/J19 -> 2.176 | O19: 12400000000000 | P19: 3000000000000 | Q19: =O19/P19 -> 4.1333333 | R19: 4.2094126e+08
A20: Ag-110m | B20: =VLOOKUP(A20,衰变常数!$A$1:$H$3800,7,FALSE) -> 3.2120989e-08 | C20: 242000000000000 | D20: 255000000000000 | E20: =C20/D20 -> 0.94901961 | G20: 37363.739 | H20: =F20/G20 -> 0 | I20: 409000 | J20: 130000 | K20: =I20/J20 -> 3.1461538 | O20: 282000000000 | P20: 63000000000 | Q20: =O20/P20 -> 4.4761905 | R20: 50731205
A21: H-3 | B21: =VLOOKUP(A21,衰变常数!$A$1:$H$3800,7,FALSE) -> 1.7828336e-09 | C21: 111000000000000 | D21: 123000000000000 | E21: =C21/D21 -> 0.90243902 | G21: 4.3133664e+10 | H21: =F21/G21 -> 0 | I21: 144000000000 | J21: 143000000000 | K21: =I21/J21 -> 1.006993 | L21: 12900000000000 | M21: 1.2806281e+13 | N21: =L21/M21 -> 1.0073182
A22: C-14 | B22: =VLOOKUP(A22,衰变常数!$A$1:$H$3800,7,FALSE) -> 3.8534294e-12 | G22: 62399793 | H22: =F22/G22 -> 0 | I22: 208000000 | J22: 210000000 | K22: =I22/J22 -> 0.99047619 | L22: 18700000000 | M22: 1.8914885e+10 | N22: =L22/M22 -> 0.98863939 | O22: 22000000000 | P22: 22000000000 | Q22: =O22/P22 -> 1
A23: Co-60 | B23: =VLOOKUP(A23,衰变常数!$A$1:$H$3800,7,FALSE) -> 4.1669453e-09 | G23: 13152.273 | H23: =F23/G23 -> 0 | I23: 1100 | J23: 44000 | K23: =I23/J23 -> 0.025 | O23: 2120000000 | P23: 86000000000 | Q23: =O23/P23 -> 0.024651163 | R23: 1103732.6
A24: Ar-41 | B24: =VLOOKUP(A24,衰变常数!$A$1:$H$3800,7,FALSE) -> 0.00010539598 | G24: 4.9908883e+10 | H24: =F24/G24 -> 0 | I24: 71000000000 | R24: 52688183 | S24: 3.4534751e+08
A25: Fe-55 | B25: =VLOOKUP(A25,衰变常数!$A$1:$H$3800,7,FALSE) -> 8.004559e-09 | I25: 3000 | O25: 3200000000 | R25: 1734972
A26: Ni-63 | B26: =VLOOKUP(A26,衰变常数!$A$1:$H$3800,7,FALSE) -> 2.1704054e-10 | I26: 39 | O26: 460000000 | R26: 57843.814
A27: Rb-88 | B27: =VLOOKUP(A27,衰变常数!$A$1:$H$3800,7,FALSE) -> 0.00065000017 | C27: 1.88e+17 | I27: 1200000000 | O27: 61000000000 | R27: 1.421973e+08 | S27: 3.7219982e+08
A28: Cs-138 | B28: =VLOOKUP(A28,衰变常数!$A$1:$H$3800,7,FALSE) -> 0.0003457783 | I28: 410000000 | O28: 39000000000 | R28: 58280368 | S28: 1.8617321e+08
A29: SUM | C29: =SUM(C2:C28) -> 3.378513e+18 | D29: =SUM(D2:D28) -> 3.339478e+18 | E29: =SUM(E2:E28) -> 19.116304 | F29: =SUM(F2:F28) -> 0 | G29: =SUM(G2:G28) -> 1.3958583e+11 | H29: =SUM(H2:H28) -> 0 | I29: =SUM(I2:I28) -> 5.6275015e+11 | J29: =SUM(J2:J28) -> 664203600170 | ... S29: =SUM(S2:S28) -> 3.9745222e+09

Sheet 过滤效率
A1: 核素 | B1: 过滤效率
A2: Kr-83m | B2: 0
A3: Kr-85 | B3: 0
A4: Kr-85m | B4: 0
A5: Kr-87 | B5: 0
A6: Kr-88 | B6: 0
A7: Xe-131m | B7: 0
A8: Xe-133 | B8: 0
A9: Xe-133m | B9: 0
A10: Xe-135 | B10: 0
A11: I-131 | B11: 0.95
A12: I-132 | B12: 0.95
A13: I-133 | B13: 0.95
... A24: Ar-41 | B24: 0

Sheet 事故释放率
R1: BOOTH | T1: UO2核芯 | AD1: 石墨晶粒 | AH1: 石墨孔隙 | AK1: 释放率计算公式
T2: 扩散参数 <1200K: 使用JULICH参数 | Y2: 扩散参数>=1200K: 使用IAEA978 | AK2: 1620 | AO2: D=D01EXP(-Q01/RT)+D02EXP(-Q02/RT) | AP2: sqrt(λ*a2/D) | AQ2: λB3/x(cothx-1/x) | AY2: 数据-PM FSAR使用 | BN2: 误差new/old | CD2: 数据-刘涛计算 | CR2: 误差new/old
A3: 核素 | B3: 400 | C3: 500 | D3: 600 | E3: 700 | F3: 800 | G3: 900 | H3: 1000 | I3: 1100 | J3: 1200 | K3: 1300 | L3: 1400 | M3: 1500 | N3: 1570 | O3: 1620 | R3: λ(1/s) | S3: R(J/mol.K) | T3: D01(m2/S) | U3: Q01(J/mol) | V3: D02(m2/S) | W3: Q02(J/mol) | X3: a(m) | Y3: D01(m2/S) | Z3: Q01(J/mol) | AA3: D02(m2/S) | AB3: Q02(J/mol) | AC3: a(m) | AD3: D0(m2/S) | AE3: Q0(J/mol) | AF3: a(m) | AG3: B铀污染 | AH3: D0(m2/S) | AI3: Q0(J/mol) | AJ3: a(m) | AK3: T/C | AL3: T/K | AM3: 核芯破损率 | AN3: 核芯a | AO3: 核芯D | AP3: 核芯x | AQ3: 核芯释放率 | AR3: 晶粒D | AS3: 晶粒x | AT3: 晶粒释放率 | AU3: 孔隙D | AV3: 孔隙x | AW3: 总释放率 | AZ3: 400 | BA3: 500 | BB3: 600 | BC3: 700 | BD3: 800 | BE3: 900 | BF3: 1000 | BG3: 1100 | BH3: 1200 | BI3: 1300 | BJ3: 1400 | BK3: 1500 | BL3: 1570 | BM3: 1620 | BO3: 400 | BP3: 500 | BQ3: 600 | BR3: 700 | BS3: 800 | BT3: 900 | BU3: 1000 | BV3: 1100 | BW3: 1200 | BX3: 1300 | BY3: 1400 | BZ3: 1500 | CA3: 1570 | CB3: 1620 | CS3: 400 | CT3: 500 | CU3: 600 | CV3: 700 | CW3: 800 | CX3: 900 | CY3: 1000 | CZ3: 1100 | DA3: 1200 | DB3: 1300 | DC3: 1400 | DD3: 1500 | DE3: 1570 | DF3: 1620
A4: Kr-83m | B4: 1.8390442e-11 | C4: 2.9871502e-11 | D4: 4.3425478e-11 | E4: 5.8463963e-11 | F4: 7.4472584e-11 | G4: 9.103463e-11 | H4: 1.0782765e-10 | I4: 1.2461001e-10 | J4: 2.0833361e-10 | K4: 4.9354874e-10 | L4: 1.3614977e-09 | M4: 4.1512268e-09 | N4: 1.3860548e-08 | O4: 1.3860548e-08 | P4: BOOTH | R4: =VLOOKUP(A4,衰变常数!$A$1:$H$3800,7,FALSE) -> 0.0001052136 | S4: 8.3143 | T4: 2.5e-18 | U4: 41870 | V4: 0 | W4: 0 | X4: 1e-05 | Y4: 8.8e-15 | Z4: 54000 | AA4: 0.6 | AB4: 480000 | AC4: 0.00025 | AD4: 6e-17 | AE4: 62800 | AF4: 6e-06 | AG4: 7e-07 | AH4: 6.2e-07 | AI4: 0 | AJ4: 0.03 | AK4: =AK$2 -> 1620 | AL4: =AK4+273.15 -> 1893.15 | AM4: =0.00016+0.0005*MAX(0,$AK4-1200)/(1620-1200) -> 0.00066 | AN4: =IF(AK4<1200,$X4,$AC4) -> 0.00025 | AO4: =IF($AK4<1200,$T4*EXP(-$U4/$S4/AL4)+$V4*EXP(-$W4/$S4/AL4),$Y4*EXP(-$Z4/$S4/AL4)+$AA4*EXP(-$AB4/$S4/AL4)) -> 3.4505088e-14 | AP4: =SQRT($R4*AN4*AN4/AO4) -> 13.804935 | AQ4: =$R4*AM4*3/AP4*(IFERROR(COSH(AP4)/SINH(AP4),1)-1/AP4) -> 1.3997346e-08 | AR4: =$AD4*EXP(-$AE4/$S4/AL4) -> 1.1102273e-18 | AS4: =SQRT($R4*$AF4*$AF4/AR4) -> 58.409197 | AT4: =$R4*$AG4*3/AS4*(IFERROR(COSH(AS4)/SINH(AS4),1)-1/AS4) -> 3.7180067e-12 | AU4: =$AH4*EXP(-$AI4/$S4/AL4) -> 6.2e-07 | AV4: =SQRT($R4*$AJ4*$AJ4/AU4) -> 0.39080611 | AW4: =(AQ4+AT4)*3/AV4*(IFERROR(COSH(AV4)/SINH(AV4),1)-1/AV4) -> 1.3860548e-08 | AY4: Kr-83m | AZ4: 1.8363515e-11 | BA4: 2.9840642e-11 | BB4: 4.339838e-11 | BC4: 5.8450951e-11 | BD4: 1.92e-11 | BE4: 3.51e-11 | BF4: 5.83e-11 | BG4: 9e-11 | BH4: 1.31e-10 | BI4: 5.09e-10 | BJ4: 1.43e-09 | BK4: 4.44e-09 | BL4: 1.51e-08 | BM4: 1.51e-08 | BO4: =B4/AZ4 -> 1.0014663 | BP4: =C4/BA4 -> 1.0010342 | BQ4: =D4/BB4 -> 1.0006244 | BR4: =E4/BC4 -> 1.0002226 | BS4: =F4/BD4 -> 3.8787804 | BT4: =G4/BE4 -> 2.5935792 | BU4: =H4/BF4 -> 1.8495309 | BV4: =I4/BG4 -> 1.3845557 | ... CB4: =O4/BM4 -> 0.9179171 | CD4: 1.8363515e-11 | CE4: 2.9840642e-11 | CF4: 4.339838e-11 | CG4: 5.8450951e-11 | CH4: 7.4485667e-11 | CI4: 9.108662e-11 | CJ4: 1.0793145e-10 | CK4: 1.2477808e-10 | CL4: 2.0893818e-10 | CM4: 5.0319578e-10 | CN4: 1.3990458e-09 | CO4: 4.2846263e-09 | CP4: 1.3830421e-08 | CQ4: 1.3830421e-08 | CS4: =B4/CD4 -> 1.0014663 | CT4: =C4/CE4 -> 1.0010342 | CU4: =D4/CF4 -> 1.0006244 | CV4: =E4/CG4 -> 1.0002226 | CW4: =F4/CH4 -> 0.99982436 | CX4: =G4/CI4 -> 0.99942922 | CY4: =H4/CJ4 -> 0.99903829 | CZ4: =I4/CK4 -> 0.99865307 | ... DF4: =O4/CQ4 -> 1.0021783
A5: Kr-85 | B5: =AZ5 -> 3.996e-14 | C5: =BA5 -> 3.996e-14 | D5: =BB5 -> 3.996e-14 | E5: =BC5 -> 1.324e-13 | F5: =BD5 -> 1.987e-13 | G5: =BE5 -> 4.04e-13 | H5: =BF5 -> 9.44e-13 | I5: =BG5 -> 2.12e-12 | ... O5: =BM5 -> 2.31e-10 | P5: Fresco-II | R5: =VLOOKUP(A5,衰变常数!$A$1:$H$3800,7,FALSE) -> 2.0420706e-09 | S5: 8.3143 | T5: 2.5e-18 | U5: 41870 | V5: 0 | W5: 0 | X5: 1e-05 | Y5: 8.8e-15 | Z5: 54000 | AA5: 0.6 | AB5: 480000 | AC5: 0.00025 | AD5: 6e-17 | AE5: 62800 | AF5: 6e-06 | AG5: 7e-07 | AH5: 6.2e-07 | AI5: 0 | AJ5: 0.03 | AK5: =AK$2 -> 1620 | AL5: =AK5+273.15 -> 1893.15 | AM5: =0.00016+0.0005*MAX(0,$AK5-1200)/(1620-1200) -> 0.00066 | AN5: =IF(AK5<1200,$X5,$AC5) -> 0.00025 | AO5: =IF($AK5<1200,$T5*EXP(-$U5/$S5/AL5)+$V5*EXP(-$W5/$S5/AL5),$Y5*EXP(-$Z5/$S5/AL5)+$AA5*EXP(-$AB5/$S5/AL5)) -> 3.4505088e-14 | AP5: =SQRT($R5*AN5*AN5/AO5) -> 0.060818236 | AQ5: =$R5*AM5*3/AP5*(IFERROR(COSH(AP5)/SINH(AP5),1)-1/AP5) -> 1.3474344e-12 | AR5: =$AD5*EXP(-$AE5/$S5/AL5) -> 1.1102273e-18 | AS5: =SQRT($R5*$AF5*$AF5/AR5) -> 0.25732423 | AT5: =$R5*$AG5*3/AS5*(IFERROR(COSH(AS5)/SINH(AS5),1)-1/AS5) -> 1.4231788e-15 | AU5: =$AH5*EXP(-$AI5/$S5/AL5) -> 6.2e-07 | AV5: =SQRT($R5*$AJ5*$AJ5/AU5) -> 0.0017217131 | AW5: =(AQ5+AT5)*3/AV5*(IFERROR(COSH(AV5)/SINH(AV5),1)-1/AV5) -> 1.3488573e-12 | AY5: Kr85 | AZ5: 3.996e-14 | BA5: 3.996e-14 | BB5: 3.996e-14 | BC5: 1.324e-13 | BD5: 1.987e-13 | BE5: 4.04e-13 | BF5: 9.44e-13 | BG5: 2.12e-12 | BH5: 1.15e-11 | BI5: 2.99e-11 | BJ5: 5.6e-11 | BK5: 1.27e-10 | BL5: 1.77e-10 | BM5: 2.31e-10 | BO5: =B5/AZ5 -> 1 | BP5: =C5/BA5 -> 1 | BQ5: =D5/BB5 -> 1 | BR5: =E5/BC5 -> 1 | BS5: =F5/BD5 -> 1 | BT5: =G5/BE5 -> 1 | BU5: =H5/BF5 -> 1 | BV5: =I5/BG5 -> 1 | ... CB5: =O5/BM5 -> 1
A6: Kr-85m | B6: 1.1821432e-11 | C6: 1.9198999e-11 | D6: 2.79061e-11 | E6: 3.7563661e-11 | F6: 4.7840496e-11 | G6: 5.8468492e-11 | H6: 6.9240371e-11 | I6: 8.0000986e-11 | J6: 1.3362633e-10 | K6: 3.1629446e-10 | L6: 8.6983419e-10 | M6: 2.6281804e-09 | N6: 8.5185762e-09 | O6: 8.5185762e-09 | P6: BOOTH | R6: =VLOOKUP(A6,衰变常数!$A$1:$H$3800,7,FALSE) -> 4.2977876e-05 | S6: 8.3143 | T6: 2.5e-18 | U6: 41870 | V6: 0 | W6: 0 | X6: 1e-05 | Y6: 8.8e-15 | Z6: 54000 | AA6: 0.6 | AB6: 480000 | AC6: 0.00025 | AD6: 6e-17 | AE6: 62800 | AF6: 6e-06 | AG6: 7e-07 | AH6: 6.2e-07 | AI6: 0 | AJ6: 0.03 | AK6: =AK$2 -> 1620 | AL6: =AK6+273.15 -> 1893.15 | AM6: =0.00016+0.0005*MAX(0,$AK6-1200)/(1620-1200) -> 0.00066 | AN6: =IF(AK6<1200,$X6,$AC6) -> 0.00025 | AO6: =IF($AK6<1200,$T6*EXP(-$U6/$S6/AL6)+$V6*EXP(-$W6/$S6/AL6),$Y6*EXP(-$Z6/$S6/AL6)+$AA6*EXP(-$AB6/$S6/AL6)) -> 3.4505088e-14 | AP6: =SQRT($R6*AN6*AN6/AO6) -> 8.8230941 | AQ6: =$R6*AM6*3/AP6*(IFERROR(COSH(AP6)/SINH(AP6),1)-1/AP6) -> 8.5515904e-09 | AR6: =$AD6*EXP(-$AE6/$S6/AL6) -> 1.1102273e-18 | AS6: =SQRT($R6*$AF6*$AF6/AR6) -> 37.330841 | AT6: =$R6*$AG6*3/AS6*(IFERROR(COSH(AS6)/SINH(AS6),1)-1/AS6) -> 2.3529037e-12 | AU6: =$AH6*EXP(-$AI6/$S6/AL6) -> 6.2e-07 | AV6: =SQRT($R6*$AJ6*$AJ6/AU6) -> 0.24977438 | AW6: =(AQ6+AT6)*3/AV6*(IFERROR(COSH(AV6)/SINH(AV6),1)-1/AV6) -> 8.5185762e-09 | AY6: Kr-85m | AZ6: 1.1821346e-11 | BA6: 1.9209643e-11 | BB6: 2.7937314e-11 | BC6: 3.762727e-11 | BD6: 1.23e-11 | BE6: 2.25e-11 | BF6: 3.73e-11 | BG6: 5.76e-11 | BH6: 8.37e-11 | BI6: 3.26e-10 | BJ6: 9.13e-10 | BK6: 2.84e-09 | BL6: 9.64e-09 | BM6: 9.64e-09 | BO6: =B6/AZ6 -> 1.0000072 | BP6: =C6/BA6 -> 0.9994459 | BQ6: =D6/BB6 -> 0.99888273 | BR6: =E6/BC6 -> 0.99830951 | BS6: =F6/BD6 -> 3.8894712 | BT6: =G6/BE6 -> 2.5985996 | BU6: =H6/BF6 -> 1.8563102 | BV6: =I6/BG6 -> 1.388906 | ... CB6: =O6/BM6 -> 0.88366973 | CD6: 1.1821346e-11 | CE6: 1.9209643e-11 | CF6: 2.7937314e-11 | CG6: 3.762727e-11 | CH6: 4.7949473e-11 | CI6: 5.8636186e-11 | CJ6: 6.9479892e-11 | CK6: 8.0324758e-11 | CL6: 1.3450206e-10 | CM6: 3.2289435e-10 | CN6: 8.9497702e-10 | CO6: 2.7162118e-09 | CP6: 8.5121873e-09 | CQ6: 8.5121873e-09 | CS6: =B6/CD6 -> 1.0000072 | CT6: =C6/CE6 -> 0.9994459 | CU6: =D6/CF6 -> 0.99888273 | CV6: =E6/CG6 -> 0.99830951 | CW6: =F6/CH6 -> 0.99772725 | CX6: =G6/CI6 -> 0.99714008 | CY6: =H6/CJ6 -> 0.99655265 | CZ6: =I6/CK6 -> 0.99596921 | ... DF6: =O6/CQ6 -> 1.0007506
A7: Kr-87 | B7: 2.1966451e-11 | C7: 3.5681361e-11 | D7: 5.1873875e-11 | E7: 6.9841633e-11 | F7: 8.897054e-11 | G7: 1.0876299e-10 | H7: 1.2883385e-10 | I7: 1.4889439e-10 | J7: 2.4900333e-10 | K7: 5.9004462e-10 | L7: 1.6291638e-09 | M7: 4.9804598e-09 | N7: 1.6769789e-08 | O7: 1.6769789e-08 | P7: BOOTH | R7: =VLOOKUP(A7,衰变常数!$A$1:$H$3800,7,FALSE) -> 0.0001514083 | S7: 8.3143 | T7: 2.5e-18 | U7: 41870 | V7: 0 | W7: 0 | X7: 1e-05 | Y7: 8.8e-15 | Z7: 54000 | AA7: 0.6 | AB7: 480000 | AC7: 0.00025 | AD7: 6e-17 | AE7: 62800 | AF7: 6e-06 | AG7: 7e-07 | AH7: 6.2e-07 | AI7: 0 | AJ7: 0.03 | AK7: =AK$2 -> 1620 | AL7: =AK7+273.15 -> 1893.15 | AM7: =0.00016+0.0005*MAX(0,$AK7-1200)/(1620-1200) -> 0.00066 | AN7: =IF(AK7<1200,$X7,$AC7) -> 0.00025 | AO7: =IF($AK7<1200,$T7*EXP(-$U7/$S7/AL7)+$V7*EXP(-$W7/$S7/AL7),$Y7*EXP(-$Z7/$S7/AL7)+$AA7*EXP(-$AB7/$S7/AL7)) -> 3.4505088e-14 | AP7: =SQRT($R7*AN7*AN7/AO7) -> 16.560493 | AQ7: =$R7*AM7*3/AP7*(IFERROR(COSH(AP7)/SINH(AP7),1)-1/AP7) -> 1.7009505e-08 | AR7: =$AD7*EXP(-$AE7/$S7/AL7) -> 1.1102273e-18 | AS7: =SQRT($R7*$AF7*$AF7/AR7) -> 70.068067 | AT7: =$R7*$AG7*3/AS7*(IFERROR(COSH(AS7)/SINH(AS7),1)-1/AS7) -> 4.4730731e-12 | AU7: =$AH7*EXP(-$AI7/$S7/AL7) -> 6.2e-07 | AV7: =SQRT($R7*$AJ7*$AJ7/AU7) -> 0.46881365 | AW7: =(AQ7+AT7)*3/AV7*(IFERROR(COSH(AV7)/SINH(AV7),1)-1/AV7) -> 1.6769789e-08 | AY7: Kr-87 | AZ7: 2.1926024e-11 | BA7: 3.5629705e-11 | BB7: 5.1817634e-11 | BC7: 6.9790393e-11 | BD7: 2.32e-11 | BE7: 4.24e-11 | BF7: 7.04e-11 | BG7: 1.09e-10 | BH7: 1.58e-10 | BI7: 6.14e-10 | BJ7: 1.72e-09 | BK7: 5.36e-09 | BL7: 1.82e-08 | BM7: 1.82e-08 | BO7: =B7/AZ7 -> 1.0018438 | BP7: =C7/BA7 -> 1.0014498 | BQ7: =D7/BB7 -> 1.0010854 | BR7: =E7/BC7 -> 1.0007342 | BS7: =F7/BD7 -> 3.8349371 | BT7: =G7/BE7 -> 2.5651649 | BU7: =H7/BF7 -> 1.8300262 | BV7: =I7/BG7 -> 1.3660035 | ... CB7: =O7/BM7 -> 0.92141695 | CD7: 2.1926024e-11 | CE7: 3.5629705e-11 | CF7: 5.1817634e-11 | CG7: 6.9790393e-11 | CH7: 8.8935833e-11 | CI7: 1.0875736e-10 | CJ7: 1.2887007e-10 | CK7: 1.4898494e-10 | CL7: 2.4947203e-10 | CM7: 6.0138127e-10 | CN7: 1.6735515e-09 | CO7: 5.1388278e-09 | CP7: 1.6727638e-08 | CQ7: 1.6727638e-08 | CS7: =B7/CD7 -> 1.0018438 | CT7: =C7/CE7 -> 1.0014498 | CU7: =D7/CF7 -> 1.0010854 | CV7: =E7/CG7 -> 1.0007342 | CW7: =F7/CH7 -> 1.0003902 | CX7: =G7/CI7 -> 1.0000518 | CY7: =H7/CJ7 -> 0.9997189 | CZ7: =I7/CK7 -> 0.99939221 | ... DF7: =O7/CQ7 -> 1.0025198
A8: Kr-88 | B8: 1.4813849e-11 | C8: 2.40607e-11 | D8: 3.497572e-11 | E8: 4.7084475e-11 | F8: 5.9972329e-11 | G8: 7.3303479e-11 | H8: 8.6818181e-11 | I8: 1.0032189e-10 | J8: 1.6765789e-10 | K8: 3.9703921e-10 | L8: 1.0937996e-09 | M8: 3.3219459e-09 | N8: 1.0951683e-08 | O8: 1.0951683e-08 | P8: BOOTH | R8: =VLOOKUP(A8,衰变常数!$A$1:$H$3800,7,FALSE) -> 6.7796086e-05 | S8: 8.3143 | T8: 2.5e-18 | U8: 41870 | V8: 0 | W8: 0 | X8: 1e-05 | Y8: 8.8e-15 | Z8: 54000 | AA8: 0.6 | AB8: 480000 | AC8: 0.00025 | AD8: 6e-17 | AE8: 62800 | AF8: 6e-06 | AG8: 7e-07 | AH8: 6.2e-07 | AI8: 0 | AJ8: 0.03 | AK8: =AK$2 -> 1620 | AL8: =AK8+273.15 -> 1893.15 | AM8: =0.00016+0.0005*MAX(0,$AK8-1200)/(1620-1200) -> 0.00066 | AN8: =IF(AK8<1200,$X8,$AC8) -> 0.00025 | AO8: =IF($AK8<1200,$T8*EXP(-$U8/$S8/AL8)+$V8*EXP(-$W8/$S8/AL8),$Y8*EXP(-$Z8/$S8/AL8)+$AA8*EXP(-$AB8/$S8/AL8)) -> 3.4505088e-14 | AP8: =SQRT($R8*AN8*AN8/AO8) -> 11.081556 | AQ8: =$R8*AM8*3/AP8*(IFERROR(COSH(AP8)/SINH(AP8),1)-1/AP8) -> 1.1020363e-08 | AR8: =$AD8*EXP(-$AE8/$S8/AL8) -> 1.1102273e-18 | AS8: =SQRT($R8*$AF8*$AF8/AR8) -> 46.886478 | AT8: =$R8*$AG8*3/AS8*(IFERROR(COSH(AS8)/SINH(AS8),1)-1/AS8) -> 2.9717578e-12 | AU8: =$AH8*EXP(-$AI8/$S8/AL8) -> 6.2e-07 | AV8: =SQRT($R8*$AJ8*$AJ8/AU8) -> 0.31370954 | AW8: =(AQ8+AT8)*3/AV8*(IFERROR(COSH(AV8)/SINH(AV8),1)-1/AV8) -> 1.0951683e-08 | AY8: Kr-88 | AZ8: 1.4916035e-11 | BA8: 2.42385e-11 | BB8: 3.5250972e-11 | BC8: 4.7477644e-11 | BD8: 1.56e-11 | BE8: 2.84e-11 | BF8: 4.72e-11 | BG8: 7.28e-11 | BH8: 1.06e-10 | BI8: 4.12e-10 | BJ8: 1.15e-09 | BK8: 3.6e-09 | BL8: 1.22e-08 | BM8: 1.22e-08 | BO8: =B8/AZ8 -> 0.99314924 | BP8: =C8/BA8 -> 0.99266458 | BQ8: =D8/BB8 -> 0.99219166 | BR8: =E8/BC8 -> 0.99171886 | BS8: =F8/BD8 -> 3.8443801 | BT8: =G8/BE8 -> 2.5811084 | BU8: =H8/BF8 -> 1.8393683 | BV8: =I8/BG8 -> 1.378048 | ... CB8: =O8/BM8 -> 0.89767889 | CD8: 1.4916035e-11 | CE8: 2.42385e-11 | CF8: 3.5250972e-11 | CG8: 4.7477644e-11 | CH8: 6.0502078e-11 | CI8: 7.3986446e-11 | CJ8: 8.7668906e-11 | CK8: 1.0135283e-10 | CL8: 1.697131e-10 | CM8: 4.0818268e-10 | CN8: 1.1334152e-09 | CO8: 3.4580923e-09 | CP8: 1.1027557e-08 | CQ8: 1.1027557e-08 | CS8: =B8/CD8 -> 0.99314924 | CT8: =C8/CE8 -> 0.99266458 | CU8: =D8/CF8 -> 0.99219166 | CV8: =E8/CG8 -> 0.99171886 | CW8: =F8/CH8 -> 0.99124413 | CX8: =G8/CI8 -> 0.99076902 | CY8: =H8/CJ8 -> 0.99029617 | CZ8: =I8/CK8 -> 0.98982822 | ... DF8: =O8/CQ8 -> 0.99311952
A9: Xe-131m | B9: 1.4880346e-12 | C9: 2.4070193e-12 | D9: 3.4832989e-12 | E9: 4.6670845e-12 | F9: 5.9156922e-12 | G9: 7.1952894e-12 | H9: 8.4803688e-12 | I9: 9.7524157e-12 | J9: 1.6004321e-11 | K9: 3.7300291e-11 | L9: 9.6134982e-11 | M9: 2.3355957e-10 | N9: 4.1450759e-10 | O9: 4.1450759e-10 | P9: BOOTH | R9: =VLOOKUP(A9,衰变常数!$A$1:$H$3800,7,FALSE) -> 6.7757912e-07 | S9: 8.3143 | T9: 2.5e-18 | U9: 41870 | V9: 0 | W9: 0 | X9: 1e-05 | Y9: 8.8e-15 | Z9: 54000 | AA9: 0.6 | AB9: 480000 | AC9: 0.00025 | AD9: 3e-18 | AE9: 41870 | AF9: 6e-06 | AG9: 7e-07 | AH9: 5e-07 | AI9: 0 | AJ9: 0.03 | AK9: =AK$2 -> 1620 | AL9: =AK9+273.15 -> 1893.15 | AM9: =0.00016+0.0005*MAX(0,$AK9-1200)/(1620-1200) -> 0.00066 | AN9: =IF(AK9<1200,$X9,$AC9) -> 0.00025 | AO9: =IF($AK9<1200,$T9*EXP(-$U9/$S9/AL9)+$V9*EXP(-$W9/$S9/AL9),$Y9*EXP(-$Z9/$S9/AL9)+$AA9*EXP(-$AB9/$S9/AL9)) -> 3.4505088e-14 | AP9: =SQRT($R9*AN9*AN9/AO9) -> 1.1078436 | AQ9: =$R9*AM9*3/AP9*(IFERROR(COSH(AP9)/SINH(AP9),1)-1/AP9) -> 4.1442156e-10 | AR9: =$AD9*EXP(-$AE9/$S9/AL9) -> 2.0983103e-19 | AS9: =SQRT($R9*$AF9*$AF9/AR9) -> 10.781927 | AT9: =$R9*$AG9*3/AS9*(IFERROR(COSH(AS9)/SINH(AS9),1)-1/AS9) -> 1.1973219e-13 | AU9: =$AH9*EXP(-$AI9/$S9/AL9) -> 5e-07 | AV9: =SQRT($R9*$AJ9*$AJ9/AU9) -> 0.034923379 | AW9: =(AQ9+AT9)*3/AV9*(IFERROR(COSH(AV9)/SINH(AV9),1)-1/AV9) -> 4.1450759e-10 | AY9: Xe-131m | AZ9: 1.4830566e-12 | BA9: 2.4063556e-12 | BB9: 3.4946656e-12 | BC9: 4.7004881e-12 | BD9: 1.53e-12 | BE9: 2.8e-12 | BF9: 4.66e-12 | BG9: 7.18e-12 | BH9: 1.04e-11 | BI9: 4.06e-11 | BJ9: 1.14e-10 | BK9: 3.55e-10 | BL9: 1.2e-09 | BM9: 1.2e-09 | BO9: =B9/AZ9 -> 1.0033566 | BP9: =C9/BA9 -> 1.0002758 | BQ9: =D9/BB9 -> 0.99674741 | BR9: =E9/BC9 -> 0.99289359 | BS9: =F9/BD9 -> 3.8664655 | BT9: =G9/BE9 -> 2.5697462 | BU9: =H9/BF9 -> 1.8198216 | BV9: =I9/BG9 -> 1.3582752 | ... CB9: =O9/BM9 -> 0.34542299 | CD9: 1.4830566e-12 | CE9: 2.4063556e-12 | CF9: 3.4946656e-12 | CG9: 4.7004881e-12 | CH9: 5.9825249e-12 | CI9: 7.3074748e-12 | CJ9: 8.6496801e-12 | CK9: 9.9899938e-12 | CL9: 1.6751539e-11 | CM9: 3.7785774e-11 | CN9: 9.8099454e-11 | CO9: 2.3898219e-10 | CP9: 4.0900239e-10 | CQ9: 4.0900239e-10 | CS9: =B9/CD9 -> 1.0033566 | CT9: =C9/CE9 -> 1.0002758 | CU9: =D9/CF9 -> 0.99674741 | CV9: =E9/CG9 -> 0.99289359 | CW9: =F9/CH9 -> 0.98882868 | CX9: =G9/CI9 -> 0.98464787 | CY9: =H9/CJ9 -> 0.98042572 | CZ9: =I9/CK9 -> 0.9762184 | ... DF9: =O9/CQ9 -> 1.0134601
A10: Xe-133 | B10: 2.2393604e-12 | C10: 3.6258491e-12 | D10: 5.2531222e-12 | E10: 7.0473512e-12 | F10: 8.9449535e-12 | G10: 1.0895246e-11 | H10: 1.285974e-11 | I10: 1.4810232e-11 | J10: 2.4486425e-11 | K10: 5.7471123e-11 | L10: 1.5215996e-10 | M10: 4.057302e-10 | N10: 8.6190938e-10 | O10: 8.6190938e-10 | P10: BOOTH | R10: =VLOOKUP(A10,衰变常数!$A$1:$H$3800,7,FALSE) -> 1.5301424e-06 | S10: 8.3143 | T10: 2.5e-18 | U10: 41870 | V10: 0 | W10: 0 | X10: 1e-05 | Y10: 8.8e-15 | Z10: 54000 | AA10: 0.6 | AB10: 480000 | AC10: 0.00025 | AD10: 3e-18 | AE10: 41870 | AF10: 6e-06 | AG10: 7e-07 | AH10: 5e-07 | AI10: 0 | AJ10: 0.03 | AK10: =AK$2 -> 1620 | AL10: =AK10+273.15 -> 1893.15 | AM10: =0.00016+0.0005*MAX(0,$AK10-1200)/(1620-1200) -> 0.00066 | AN10: =IF(AK10<1200,$X10,$AC10) -> 0.00025 | AO10: =IF($AK10<1200,$T10*EXP(-$U10/$S10/AL10)+$V10*EXP(-$W10/$S10/AL10),$Y10*EXP(-$Z10/$S10/AL10)+$AA10*EXP(-$AB10/$S10/AL10)) -> 3.4505088e-14 | AP10: =SQRT($R10*AN10*AN10/AO10) -> 1.6648088 | AQ10: =$R10*AM10*3/AP10*(IFERROR(COSH(AP10)/SINH(AP10),1)-1/AP10) -> 8.6188155e-10 | AR10: =$AD10*EXP(-$AE10/$S10/AL10) -> 2.0983103e-19 | AS10: =SQRT($R10*$AF10*$AF10/AR10) -> 16.202511 | AT10: =$R10*$AG10*3/AS10*(IFERROR(COSH(AS10)/SINH(AS10),1)-1/AS10) -> 1.8608092e-13 | AU10: =$AH10*EXP(-$AI10/$S10/AL10) -> 5e-07 | AV10: =SQRT($R10*$AJ10*$AJ10/AU10) -> 0.05248101 | AW10: =(AQ10+AT10)*3/AV10*(IFERROR(COSH(AV10)/SINH(AV10),1)-1/AV10) -> 8.6190938e-10 | AY10: Xe-133 | AZ10: 2.2369016e-12 | BA10: 3.6295182e-12 | BB10: 5.2710216e-12 | BC10: 7.0897697e-12 | BD10: 2.32e-12 | BE10: 4.24e-12 | BF10: 7.04e-12 | BG10: 1.09e-11 | BH10: 1.58e-11 | BI10: 6.14e-11 | BJ10: 1.72e-10 | BK10: 5.36e-10 | BL10: 1.82e-09 | BM10: 1.82e-09 | BO10: =B10/AZ10 -> 1.0010992 | BP10: =C10/BA10 -> 0.99898911 | BQ10: =D10/BB10 -> 0.99660418 | BR10: =E10/BC10 -> 0.99401693 | BS10: =F10/BD10 -> 3.8555834 | BT10: =G10/BE10 -> 2.5696335 | BU10: =H10/BF10 -> 1.8266676 | BV10: =I10/BG10 -> 1.3587369 | ... CB10: =O10/BM10 -> 0.47357658 | CD10: 2.2369016e-12 | CE10: 3.6295182e-12 | CF10: 5.2710216e-12 | CG10: 7.0897697e-12 | CH10: 9.0234723e-12 | CI10: 1.1021901e-11 | CJ10: 1.3046356e-11 | CK10: 1.5067958e-11 | CL10: 2.526643e-11 | CM10: 5.8457551e-11 | CN10: 1.5596843e-10 | CO10: 4.1756855e-10 | CP10: 8.5670676e-10 | CQ10: 8.5670676e-10 | CS10: =B10/CD10 -> 1.0010992 | CT10: =C10/CE10 -> 0.99898911 | CU10: =D10/CF10 -> 0.99660418 | CV10: =E10/CG10 -> 0.99401693 | CW10: =F10/CH10 -> 0.99129839 | CX10: =G10/CI10 -> 0.98850883 | CY10: =H10/CJ10 -> 0.98569594 | CZ10: =I10/CK10 -> 0.98289581 | ... DF10: =O10/CQ10 -> 1.0060728
A11: Xe-133m | B11: 3.4677769e-12 | C11: 5.6186343e-12 | D11: 8.1467822e-12 | E11: 1.0939087e-11 | F11: 1.3897798e-11 | G11: 1.6944681e-11 | H11: 2.0020021e-11 | I11: 2.3079778e-11 | J11: 3.8354721e-11 | K11: 9.0450634e-11 | L11: 2.4376219e-10 | M11: 6.8951879e-10 | N11: 1.7549836e-09 | O11: 1.7549836e-09 | P11: BOOTH | R11: =VLOOKUP(A11,衰变常数!$A$1:$H$3800,7,FALSE) -> 3.6632588e-06 | S11: 8.3143 | T11: 2.5e-18 | U11: 41870 | V11: 0 | W11: 0 | X11: 1e-05 | Y11: 8.8e-15 | Z11: 54000 | AA11: 0.6 | AB11: 480000 | AC11: 0.00025 | AD11: 3e-18 | AE11: 41870 | AF11: 6e-06 | AG11: 7e-07 | AH11: 5e-07 | AI11: 0 | AJ11: 0.03 | AK11: =AK$2 -> 1620 | AL11: =AK11+273.15 -> 1893.15 | AM11: =0.00016+0.0005*MAX(0,$AK11-1200)/(1620-1200) -> 0.00066 | AN11: =IF(AK11<1200,$X11,$AC11) -> 0.00025 | AO11: =IF($AK11<1200,$T11*EXP(-$U11/$S11/AL11)+$V11*EXP(-$W11/$S11/AL11),$Y11*EXP(-$Z11/$S11/AL11)+$AA11*EXP(-$AB11/$S11/AL11)) -> 3.4505088e-14 | AP11: =SQRT($R11*AN11*AN11/AO11) -> 2.5759192 | AQ11: =$R11*AM11*3/AP11*(IFERROR(COSH(AP11)/SINH(AP11),1)-1/AP11) -> 1.7554604e-09 | AR11: =$AD11*EXP(-$AE11/$S11/AL11) -> 2.0983103e-19 | AS11: =SQRT($R11*$AF11*$AF11/AR11) -> 25.069761 | AT11: =$R11*$AG11*3/AS11*(IFERROR(COSH(AS11)/SINH(AS11),1)-1/AS11) -> 2.9461733e-13 | AU11: =$AH11*EXP(-$AI11/$S11/AL11) -> 5e-07 | AV11: =SQRT($R11*$AJ11*$AJ11/AU11) -> 0.081202622 | AW11: =(AQ11+AT11)*3/AV11*(IFERROR(COSH(AV11)/SINH(AV11),1)-1/AV11) -> 1.7549836e-09 | AY11: Xe-133m | AZ11: 1.0915816e-11 | BA11: 1.7711621e-11 | BB11: 2.5721964e-11 | BC11: 3.459724e-11 | BD11: 3.59e-12 | BE11: 6.55e-12 | BF11: 1.09e-11 | BG11: 1.68e-11 | BH11: 2.44e-11 | BI11: 9.48e-11 | BJ11: 2.66e-10 | BK11: 8.28e-10 | BL11: 2.81e-09 | BM11: 2.81e-09 | BO11: =B11/AZ11 -> 0.3176837 | BP11: =C11/BA11 -> 0.3172287 | BQ11: =D11/BB11 -> 0.31672473 | BR11: =E11/BC11 -> 0.31618381 | BS11: =F11/BD11 -> 3.8712529 | BT11: =G11/BE11 -> 2.5869742 | BU11: =H11/BF11 -> 1.8366992 | BV11: =I11/BG11 -> 1.3737963 | ... CB11: =O11/BM11 -> 0.62454934 | CD11: 3.4654575e-12 | CE11: 5.6009062e-12 | CF11: 8.1339993e-12 | CG11: 1.0940608e-11 | CH11: 1.3924609e-11 | CI11: 1.7008493e-11 | CJ11: 2.0132539e-11 | CK11: 2.3252182e-11 | CL11: 3.8989998e-11 | CM11: 9.1786085e-11 | CN11: 2.4929993e-10 | CO11: 7.0825837e-10 | CP11: 1.7423047e-09 | CQ11: 1.7423047e-09 | CS11: =B11/CD11 -> 1.0006693 | CT11: =C11/CE11 -> 1.0031652 | CU11: =D11/CF11 -> 1.0015715 | CV11: =E11/CG11 -> 0.999861 | CW11: =F11/CH11 -> 0.99807454 | CX11: =G11/CI11 -> 0.99624826 | CY11: =H11/CJ11 -> 0.99441117 | CZ11: =I11/CK11 -> 0.99258544 | ... DF11: =O11/CQ11 -> 1.0072771
A12: Xe-135 | B12: 8.3081017e-12 | C12: 1.3470806e-11 | D12: 1.9548683e-11 | E12: 2.6273731e-11 | F12: 3.3413562e-11 | G12: 4.0781389e-11 | H12: 4.8233859e-11 | I12: 5.5664519e-11 | J12: 9.3000768e-11 | K12: 2.2040252e-10 | L12: 6.0471801e-10 | M12: 1.8082793e-09 | N12: 5.6457572e-09 | O12: 5.6457572e-09 | P12: BOOTH | R12: =VLOOKUP(A12,衰变常数!$A$1:$H$3800,7,FALSE) -> 2.1065742e-05 | S12: 8.3143 | T12: 2.5e-18 | U12: 41870 | V12: 0 | W12: 0 | X12: 1e-05 | Y12: 8.8e-15 | Z12: 54000 | AA12: 0.6 | AB12: 480000 | AC12: 0.00025 | AD12: 3e-18 | AE12: 41870 | AF12: 6e-06 | AG12: 7e-07 | AH12: 5e-07 | AI12: 0 | AJ12: 0.03 | AK12: =AK$2 -> 1620 | AL12: =AK12+273.15 -> 1893.15 | AM12: =0.00016+0.0005*MAX(0,$AK12-1200)/(1620-1200) -> 0.00066 | AN12: =IF(AK12<1200,$X12,$AC12) -> 0.00025 | AO12: =IF($AK12<1200,$T12*EXP(-$U12/$S12/AL12)+$V12*EXP(-$W12/$S12/AL12),$Y12*EXP(-$Z12/$S12/AL12)+$AA12*EXP(-$AB12/$S12/AL12)) -> 3.4505088e-14 | AP12: =SQRT($R12*AN12*AN12/AO12) -> 6.1771311 | AQ12: =$R12*AM12*3/AP12*(IFERROR(COSH(AP12)/SINH(AP12),1)-1/AP12) -> 5.65929e-09 | AR12: =$AD12*EXP(-$AE12/$S12/AL12) -> 2.0983103e-19 | AS12: =SQRT($R12*$AF12*$AF12/AR12) -> 60.118035 | AT12: =$R12*$AG12*3/AS12*(IFERROR(COSH(AS12)/SINH(AS12),1)-1/AS12) -> 7.2361323e-13 | AU12: =$AH12*EXP(-$AI12/$S12/AL12) -> 5e-07 | AV12: =SQRT($R12*$AJ12*$AJ12/AU12) -> 0.19472631 | AW12: =(AQ12+AT12)*3/AV12*(IFERROR(COSH(AV12)/SINH(AV12),1)-1/AV12) -> 5.6457572e-09 | AY12: Xe-135 | AZ12: 8.2951085e-12 | BA12: 1.3459352e-11 | BB12: 1.9546544e-11 | BC12: 2.6291013e-11 | BD12: 8.64e-12 | BE12: 1.58e-11 | BF12: 2.62e-11 | BG12: 4.04e-11 | BH12: 5.88e-11 | BI12: 2.29e-10 | BJ12: 6.41e-10 | BK12: 2e-09 | BL12: 6.77e-09 | BM12: 6.77e-09 | BO12: =B12/AZ12 -> 1.0015664 | BP12: =C12/BA12 -> 1.000851 | BQ12: =D12/BB12 -> 1.0001094 | BR12: =E12/BC12 -> 0.99934267 | BS12: =F12/BD12 -> 3.8673105 | BT12: =G12/BE12 -> 2.5811005 | BU12: =H12/BF12 -> 1.840987 | BV12: =I12/BG12 -> 1.3778346 | ... CB12: =O12/BM12 -> 0.83393755 | CD12: 8.2951085e-12 | CE12: 1.3459352e-11 | CF12: 1.9546544e-11 | CG12: 2.6291013e-11 | CH12: 3.3461767e-11 | CI12: 4.0872545e-11 | CJ12: 4.8379837e-11 | CK12: 5.5876549e-11 | CL12: 9.3695573e-11 | CM12: 2.2458874e-10 | CN12: 6.2105186e-10 | CO12: 1.8653147e-09 | CP12: 5.6298462e-09 | CQ12: 5.6298462e-09 | CS12: =B12/CD12 -> 1.0015664 | CT12: =C12/CE12 -> 1.000851 | CU12: =D12/CF12 -> 1.0001094 | CV12: =E12/CG12 -> 0.99934267 | CW12: =F12/CH12 -> 0.99855941 | CX12: =G12/CI12 -> 0.99776974 | CY12: =H12/CJ12 -> 0.99698265 | CZ12: =I12/CK12 -> 0.99620539 | ... DF12: =O12/CQ12 -> 1.0028262
A13: I-131 | B13: 2.9010969e-14 | C13: 1.2335837e-13 | D13: 3.7675325e-13 | E13: 9.1446819e-13 | F13: 1.8798051e-12 | G13: 3.4125126e-12 | H13: 5.6299776e-12 | I13: 8.614389e-12 | J13: 1.9532599e-11 | K13: 4.580465e-11 | L13: 1.1992063e-10 | M13: 3.064459e-10 | N13: 5.9156526e-10 | O13: 5.9156526e-10 | P13: BOOTH | R13: =VLOOKUP(A13,衰变常数!$A$1:$H$3800,7,FALSE) -> 9.9966812e-07 | S13: 8.3143 | T13: 2e-15 | U13: 125600 | V13: 0 | W13: 0 | X13: 1e-05 | Y13: 8.8e-15 | Z13: 54000 | AA13: 0.6 | AB13: 480000 | AC13: 0.00025 | AD13: 2e-18 | AE13: 83750 | AF13: 6e-06 | AG13: 7e-07 | AH13: 1.5e-07 | AI13: 0 | AJ13: 0.03 | AK13: =AK$2 -> 1620 | AL13: =AK13+273.15 -> 1893.15 | AM13: =0.00016+0.0005*MAX(0,$AK13-1200)/(1620-1200) -> 0.00066 | AN13: =IF(AK13<1200,$X13,$AC13) -> 0.00025 | AO13: =IF($AK13<1200,$T13*EXP(-$U13/$S13/AL13)+$V13*EXP(-$W13/$S13/AL13),$Y13*EXP(-$Z13/$S13/AL13)+$AA13*EXP(-$AB13/$S13/AL13)) -> 3.4505088e-14 | AP13: =SQRT($R13*AN13*AN13/AO13) -> 1.3456322 | AQ13: =$R13*AM13*3/AP13*(IFERROR(COSH(AP13)/SINH(AP13),1)-1/AP13) -> 5.9176774e-10 | AR13: =$AD13*EXP(-$AE13/$S13/AL13) -> 9.7780219e-21 | AS13: =SQRT($R13*$AF13*$AF13/AR13) -> 60.667161 | AT13: =$R13*$AG13*3/AS13*(IFERROR(COSH(AS13)/SINH(AS13),1)-1/AS13) -> 3.403323e-14 | AU13: =$AH13*EXP(-$AI13/$S13/AL13) -> 1.5e-07 | AV13: =SQRT($R13*$AJ13*$AJ13/AU13) -> 0.077446812 | AW13: =(AQ13+AT13)*3/AV13*(IFERROR(COSH(AV13)/SINH(AV13),1)-1/AV13) -> 5.9156526e-10 | AY13: I-131 | AZ13: 2.8901875e-14 | BA13: 1.2299243e-13 | BB13: 3.7598675e-13 | BC13: 9.1389578e-13 | BD13: 1.87e-12 | BE13: 3.42e-12 | BF13: 5.68e-12 | BG13: 8.77e-12 | BH13: 1.28e-11 | BI13: 4.96e-11 | BJ13: 1.39e-10 | BK13: 4.33e-10 | BL13: 1.47e-09 | BM13: 1.47e-09 | BO13: =B13/AZ13 -> 1.0037746 | BP13: =C13/BA13 -> 1.0029753 | BQ13: =D13/BB13 -> 1.0020386 | BR13: =E13/BC13 -> 1.0006263 | BS13: =F13/BD13 -> 1.0052434 | BT13: =G13/BE13 -> 0.9978107 | BU13: =H13/BF13 -> 0.99119325 | BV13: =I13/BG13 -> 0.98225644 | ... CB13: =O13/BM13 -> 0.40242535 | CD13: 2.8901875e-14 | CE13: 1.2299243e-13 | CF13: 3.7598675e-13 | CG13: 9.1389578e-13 | CH13: 1.8828345e-12 | CI13: 3.4296577e-12 | CJ13: 5.6858963e-12 | CK13: 8.7575511e-12 | CL13: 1.9499646e-11 | CM13: 4.6684282e-11 | CN13: 1.2318762e-10 | CO13: 3.1618518e-10 | CP13: 5.9000349e-10 | CQ13: 5.9000349e-10 | CS13: =B13/CD13 -> 1.0037746 | CT13: =C13/CE13 -> 1.0029753 | CU13: =D13/CF13 -> 1.0020386 | CV13: =E13/CG13 -> 1.0006263 | CW13: =F13/CH13 -> 0.99839108 | CX13: =G13/CI13 -> 0.99500093 | CY13: =H13/CJ13 -> 0.99016538 | CZ13: =I13/CK13 -> 0.98365272 | ... DF13: =O13/CQ13 -> 1.0026471
A14: I-132 | B14: 2.5737415e-13 | C14: 1.0945788e-12 | D14: 3.3445615e-12 | E14: 8.1261477e-12 | F14: 1.6734484e-11 | G14: 3.0466911e-11 | H14: 5.0477695e-11 | I14: 7.7684905e-11 | J14: 1.8012242e-10 | K14: 4.28663e-10 | L14: 1.1849086e-09 | M14: 3.6102418e-09 | N14: 1.1985879e-08 | O14: 1.1985879e-08 | P14: BOOTH | R14: =VLOOKUP(A14,衰变常数!$A$1:$H$3800,7,FALSE) -> 8.389581e-05 | S14: 8.3143 | T14: 2e-15 | U14: 125600 | V14: 0 | W14: 0 | X14: 1e-05 | Y14: 8.8e-15 | Z14: 54000 | AA14: 0.6 | AB14: 480000 | AC14: 0.00025 | AD14: 2e-18 | AE14: 83750 | AF14: 6e-06 | AG14: 7e-07 | AH14: 1.5e-07 | AI14: 0 | AJ14: 0.03 | AK14: =AK$2 -> 1620 | AL14: =AK14+273.15 -> 1893.15 | AM14: =0.00016+0.0005*MAX(0,$AK14-1200)/(1620-1200) -> 0.00066 | AN14: =IF(AK14<1200,$X14,$AC14) -> 0.00025 | AO14: =IF($AK14<1200,$T14*EXP(-$U14/$S14/AL14)+$V14*EXP(-$W14/$S14/AL14),$Y14*EXP(-$Z14/$S14/AL14)+$AA14*EXP(-$AB14/$S14/AL14)) -> 3.4505088e-14 | AP14: =SQRT($R14*AN14*AN14/AO14) -> 12.327317 | AQ14: =$R14*AM14*3/AP14*(IFERROR(COSH(AP14)/SINH(AP14),1)-1/AP14) -> 1.2382131e-08 | AR14: =$AD14*EXP(-$AE14/$S14/AL14) -> 9.7780219e-21 | AS14: =SQRT($R14*$AF14*$AF14/AR14) -> 555.771 | AT14: =$R14*$AG14*3/AS14*(IFERROR(COSH(AS14)/SINH(AS14),1)-1/AS14) -> 3.1643284e-13 | AU14: =$AH14*EXP(-$AI14/$S14/AL14) -> 1.5e-07 | AV14: =SQRT($R14*$AJ14*$AJ14/AU14) -> 0.70948915 | AW14: =(AQ14+AT14)*3/AV14*(IFERROR(COSH(AV14)/SINH(AV14),1)-1/AV14) -> 1.1985879e-08 | AY14: I-132 | AZ14: 2.5645416e-13 | BA14: 1.0913451e-12 | BB14: 3.3362322e-12 | BC14: 8.1092445e-12 | BD14: 1.72e-11 | BE14: 3.13e-11 | BF14: 5.21e-11 | BG14: 8.03e-11 | BH14: 1.17e-10 | BI14: 4.54e-10 | BJ14: 1.27e-09 | BK14: 3.97e-09 | BL14: 1.34e-08 | BM14: 1.34e-08 | BO14: =B14/AZ14 -> 1.0035873 | BP14: =C14/BA14 -> 1.002963 | BQ14: =D14/BB14 -> 1.0024966 | BR14: =E14/BC14 -> 1.0020844 | BS14: =F14/BD14 -> 0.9729351 | BT14: =G14/BE14 -> 0.97338373 | BU14: =H14/BF14 -> 0.96886171 | BV14: =I14/BG14 -> 0.96743344 | ... CB14: =O14/BM14 -> 0.89446862 | CD14: 2.5645416e-13 | CE14: 1.0913451e-12 | CF14: 3.3362322e-12 | CG14: 8.1092445e-12 | CH14: 1.67069e-11 | CI14: 3.0432281e-11 | CJ14: 5.0452496e-11 | CK14: 7.7708121e-11 | CL14: 1.807065e-10 | CM14: 4.3701441e-10 | CN14: 1.2174967e-09 | CO14: 3.7259178e-09 | CP14: 1.1958449e-08 | CQ14: 1.1958449e-08 | CS14: =B14/CD14 -> 1.0035873 | CT14: =C14/CE14 -> 1.002963 | CU14: =D14/CF14 -> 1.0024966 | CV14: =E14/CG14 -> 1.0020844 | CW14: =F14/CH14 -> 1.0016511 | CX14: =G14/CI14 -> 1.0011379 | CY14: =H14/CJ14 -> 1.0004995 | CZ14: =I14/CK14 -> 0.99970124 | ... DF14: =O14/CQ14 -> 1.0022938
A15: I-133 | B15: 8.7993955e-14 | C15: 3.7421078e-13 | D15: 1.1432949e-12 | E15: 2.7771349e-12 | F15: 5.7165233e-12 | G15: 1.0400163e-11 | H15: 1.7213182e-11 | I15: 2.6453548e-11 | J15: 6.1006454e-11 | K15: 1.4467777e-10 | L15: 3.9491715e-10 | M15: 1.158833e-09 | N15: 3.373066e-09 | O15: 3.373066e-09 | P15: BOOTH | R15: =VLOOKUP(A15,衰变常数!$A$1:$H$3800,7,FALSE) -> 9.2567732e-06 | S15: 8.3143 | T15: 2e-15 | U15: 125600 | V15: 0 | W15: 0 | X15: 1e-05 | Y15: 8.8e-15 | Z15: 54000 | AA15: 0.6 | AB15: 480000 | AC15: 0.00025 | AD15: 2e-18 | AE15: 83750 | AF15: 6e-06 | AG15: 7e-07 | AH15: 1.5e-07 | AI15: 0 | AJ15: 0.03 | AK15: =AK$2 -> 1620 | AL15: =AK15+273.15 -> 1893.15 | AM15: =0.00016+0.0005*MAX(0,$AK15-1200)/(1620-1200) -> 0.00066 | AN15: =IF(AK15<1200,$X15,$AC15) -> 0.00025 | AO15: =IF($AK15<1200,$T15*EXP(-$U15/$S15/AL15)+$V15*EXP(-$W15/$S15/AL15),$Y15*EXP(-$Z15/$S15/AL15)+$AA15*EXP(-$AB15/$S15/AL15)) -> 3.4505088e-14 | AP15: =SQRT($R15*AN15*AN15/AO15) -> 4.0947581 | AQ15: =$R15*AM15*3/AP15*(IFERROR(COSH(AP15)/SINH(AP15),1)-1/AP15) -> 3.385431e-09 | AR15: =$AD15*EXP(-$AE15/$S15/AL15) -> 9.7780219e-21 | AS15: =SQRT($R15*$AF15*$AF15/AR15) -> 184.61014 | AT15: =$R15*$AG15*3/AS15*(IFERROR(COSH(AS15)/SINH(AS15),1)-1/AS15) -> 1.047284e-13 | AU15: =$AH15*EXP(-$AI15/$S15/AL15) -> 1.5e-07 | AV15: =SQRT($R15*$AJ15*$AJ15/AU15) -> 0.23567062 | AW15: =(AQ15+AT15)*3/AV15*(IFERROR(COSH(AV15)/SINH(AV15),1)-1/AV15) -> 3.373066e-09 | AY15: I-133 | AZ15: 8.77918e-14 | BA15: 3.7359952e-13 | BB15: 1.1420904e-12 | BC15: 2.7760328e-12 | BD15: 5.71e-12 | BE15: 1.04e-11 | BF15: 1.73e-11 | BG15: 2.67e-11 | BH15: 3.89e-11 | BI15: 1.51e-10 | BJ15: 4.23e-10 | BK15: 1.32e-09 | BL15: 4.47e-09 | BM15: 4.47e-09 | BO15: =B15/AZ15 -> 1.0023027 | BP15: =C15/BA15 -> 1.0016361 | BQ15: =D15/BB15 -> 1.0010547 | BR15: =E15/BC15 -> 1.000397 | BS15: =F15/BD15 -> 1.0011424 | BT15: =G15/BE15 -> 1.0000156 | BU15: =H15/BF15 -> 0.9949816 | BV15: =I15/BG15 -> 0.99076959 | ... CB15: =O15/BM15 -> 0.7546009 | CD15: 8.77918e-14 | CE15: 3.7359952e-13 | CF15: 1.1420904e-12 | CG15: 2.7760328e-12 | CH15: 5.719263e-12 | CI15: 1.0417865e-11 | CJ15: 1.7271373e-11 | CK15: 2.6601775e-11 | CL15: 6.186115e-11 | CM15: 1.4768661e-10 | CN15: 4.0631503e-10 | CO15: 1.197649e-09 | CP15: 3.3710722e-09 | CQ15: 3.3710722e-09 | CS15: =B15/CD15 -> 1.0023027 | CT15: =C15/CE15 -> 1.0016361 | CU15: =D15/CF15 -> 1.0010547 | CV15: =E15/CG15 -> 1.000397 | CW15: =F15/CH15 -> 0.99952096 | CX15: =G15/CI15 -> 0.99830082 | CY15: =H15/CJ15 -> 0.99663076 | CZ15: =I15/CK15 -> 0.99442794 | ... DF15: =O15/CQ15 -> 1.0005915
A16: I-134 | B16: 3.9692418e-13 | C16: 1.6880807e-12 | D16: 5.1581612e-12 | E16: 1.2533165e-11 | F16: 2.5812197e-11 | G16: 4.7000187e-11 | H16: 7.7885408e-11 | I16: 1.1989737e-10 | J16: 2.7828021e-10 | K16: 6.6269909e-10 | L16: 1.836122e-09 | M16: 5.6325174e-09 | N16: 1.9108888e-08 | O16: 1.9108888e-08 | P16: BOOTH | R16: =VLOOKUP(A16,衰变常数!$A$1:$H$3800,7,FALSE) -> 0.00022004672 | S16: 8.3143 | T16: 2e-15 | U16: 125600 | V16: 0 | W16: 0 | X16: 1e-05 | Y16: 8.8e-15 | Z16: 54000 | AA16: 0.6 | AB16: 480000 | AC16: 0.00025 | AD16: 2e-18 | AE16: 83750 | AF16: 6e-06 | AG16: 7e-07 | AH16: 1.5e-07 | AI16: 0 | AJ16: 0.03 | AK16: =AK$2 -> 1620 | AL16: =AK16+273.15 -> 1893.15 | AM16: =0.00016+0.0005*MAX(0,$AK16-1200)/(1620-1200) -> 0.00066 | AN16: =IF(AK16<1200,$X16,$AC16) -> 0.00025 | AO16: =IF($AK16<1200,$T16*EXP(-$U16/$S16/AL16)+$V16*EXP(-$W16/$S16/AL16),$Y16*EXP(-$Z16/$S16/AL16)+$AA16*EXP(-$AB16/$S16/AL16)) -> 3.4505088e-14 | AP16: =SQRT($R16*AN16*AN16/AO16) -> 19.964383 | AQ16: =$R16*AM16*3/AP16*(IFERROR(COSH(AP16)/SINH(AP16),1)-1/AP16) -> 2.0730369e-08 | AR16: =$AD16*EXP(-$AE16/$S16/AL16) -> 9.7780219e-21 | AS16: =SQRT($R16*$AF16*$AF16/AR16) -> 900.08433 | AT16: =$R16*$AG16*3/AS16*(IFERROR(COSH(AS16)/SINH(AS16),1)-1/AS16) -> 5.1282387e-13 | AU16: =$AH16*EXP(-$AI16/$S16/AL16) -> 1.5e-07 | AV16: =SQRT($R16*$AJ16*$AJ16/AU16) -> 1.1490345 | AW16: =(AQ16+AT16)*3/AV16*(IFERROR(COSH(AV16)/SINH(AV16),1)-1/AV16) -> 1.9108888e-08 | AY16: I-134 | AZ16: 3.9590184e-13 | BA16: 1.6847671e-12 | BB16: 5.150318e-12 | BC16: 1.2518669e-11 | BD16: 2.78e-11 | BE16: 5.08e-11 | BF16: 8.44e-11 | BG16: 1.3e-10 | BH16: 1.89e-10 | BI16: 7.36e-10 | BJ16: 2.06e-09 | BK16: 6.43e-09 | BL16: 2.18e-08 | BM16: 2.18e-08 | BO16: =B16/AZ16 -> 1.0025823 | BP16: =C16/BA16 -> 1.0019668 | BQ16: =D16/BB16 -> 1.0015229 | BR16: =E16/BC16 -> 1.0011579 | BS16: =F16/BD16 -> 0.9284963 | BT16: =G16/BE16 -> 0.92520053 | BU16: =H16/BF16 -> 0.9228129 | BV16: =I16/BG16 -> 0.92228746 | ... CB16: =O16/BM16 -> 0.87655449 | CD16: 3.9590184e-13 | CE16: 1.6847671e-12 | CF16: 5.150318e-12 | CG16: 1.2518669e-11 | CH16: 2.5791324e-11 | CI16: 4.697992e-11 | CJ16: 7.7886185e-11 | CK16: 1.1996213e-10 | CL16: 2.7896618e-10 | CM16: 6.7629258e-10 | CN16: 1.8885308e-09 | CO16: 5.8189356e-09 | CP16: 1.9085363e-08 | CQ16: 1.9085363e-08 | CS16: =B16/CD16 -> 1.0025823 | CT16: =C16/CE16 -> 1.0019668 | CU16: =D16/CF16 -> 1.0015229 | CV16: =E16/CG16 -> 1.0011579 | CW16: =F16/CH16 -> 1.0008093 | CX16: =G16/CI16 -> 1.0004314 | CY16: =H16/CJ16 -> 0.99999003 | CZ16: =I16/CK16 -> 0.99946014 | ... DF16: =O16/CQ16 -> 1.0012326
A17: I-135 | B17: 1.5533591e-13 | C17: 6.6061368e-13 | D17: 2.0184707e-12 | E17: 4.9037827e-12 | F17: 1.0097005e-11 | G17: 1.8378191e-11 | H17: 3.0438214e-11 | I17: 4.6821498e-11 | J17: 1.0836146e-10 | K17: 2.5757458e-10 | L17: 7.0894851e-10 | M17: 2.1330727e-09 | N17: 6.7921121e-09 | O17: 6.7921121e-09 | P17: BOOTH | R17: =VLOOKUP(A17,衰变常数!$A$1:$H$3800,7,FALSE) -> 2.9306071e-05 | S17: 8.3143 | T17: 2e-15 | U17: 125600 | V17: 0 | W17: 0 | X17: 1e-05 | Y17: 8.8e-15 | Z17: 54000 | AA17: 0.6 | AB17: 480000 | AC17: 0.00025 | AD17: 2e-18 | AE17: 83750 | AF17: 6e-06 | AG17: 7e-07 | AH17: 1.5e-07 | AI17: 0 | AJ17: 0.03 | AK17: =AK$2 -> 1620 | AL17: =AK17+273.15 -> 1893.15 | AM17: =0.00016+0.0005*MAX(0,$AK17-1200)/(1620-1200) -> 0.00066 | AN17: =IF(AK17<1200,$X17,$AC17) -> 0.00025 | AO17: =IF($AK17<1200,$T17*EXP(-$U17/$S17/AL17)+$V17*EXP(-$W17/$S17/AL17),$Y17*EXP(-$Z17/$S17/AL17)+$AA17*EXP(-$AB17/$S17/AL17)) -> 3.4505088e-14 | AP17: =SQRT($R17*AN17*AN17/AO17) -> 7.2857998 | AQ17: =$R17*AM17*3/AP17*(IFERROR(COSH(AP17)/SINH(AP17),1)-1/AP17) -> 6.8711485e-09 | AR17: =$AD17*EXP(-$AE17/$S17/AL17) -> 9.7780219e-21 | AS17: =SQRT($R17*$AF17*$AF17/AR17) -> 328.47668 | AT17: =$R17*$AG17*3/AS17*(IFERROR(COSH(AS17)/SINH(AS17),1)-1/AS17) -> 1.8678766e-13 | AU17: =$AH17*EXP(-$AI17/$S17/AL17) -> 1.5e-07 | AV17: =SQRT($R17*$AJ17*$AJ17/AU17) -> 0.41932854 | AW17: =(AQ17+AT17)*3/AV17*(IFERROR(COSH(AV17)/SINH(AV17),1)-1/AV17) -> 6.7921121e-09 | AY17: I-135 | AZ17: 1.5337667e-13 | BA17: 6.5269705e-13 | BB17: 1.995289e-12 | BC17: 4.8498682e-12 | BD17: 1.01e-11 | BE17: 1.84e-11 | BF17: 3.05e-11 | BG17: 4.7e-11 | BH17: 6.84e-11 | BI17: 2.66e-10 | BJ17: 7.46e-10 | BK17: 2.32e-09 | BL17: 7.87e-09 | BM17: 7.87e-09 | BO17: =B17/AZ17 -> 1.0127741 | BP17: =C17/BA17 -> 1.0121291 | BQ17: =D17/BB17 -> 1.0116182 | BR17: =E17/BC17 -> 1.0111167 | BS17: =F17/BD17 -> 0.99970344 | BT17: =G17/BE17 -> 0.99881473 | BU17: =H17/BF17 -> 0.99797423 | BV17: =I17/BG17 -> 0.99620209 | ... CB17: =O17/BM17 -> 0.86303839 | CD17: 1.5337667e-13 | CE17: 6.5269705e-13 | CF17: 1.995289e-12 | CG17: 4.8498682e-12 | CH17: 9.9918386e-12 | CI17: 1.820053e-11 | CJ17: 3.0173953e-11 | CK17: 4.6474631e-11 | CL17: 1.0807452e-10 | CM17: 2.6018285e-10 | CN17: 7.2169219e-10 | CO17: 2.1803779e-09 | CP17: 6.7051242e-09 | CQ17: 6.7051242e-09 | CS17: =B17/CD17 -> 1.0127741 | CT17: =C17/CE17 -> 1.0121291 | CU17: =D17/CF17 -> 1.0116182 | CV17: =E17/CG17 -> 1.0111167 | CW17: =F17/CH17 -> 1.0105252 | CX17: =G17/CI17 -> 1.0097613 | CY17: =H17/CJ17 -> 1.0087579 | CZ17: =I17/CK17 -> 1.0074636 | ... DF17: =O17/CQ17 -> 1.0129733
A18: Sr-89 | B18: =AZ18 -> 4.167e-21 | C18: =BA18 -> 4.167e-21 | D18: =BB18 -> 4.167e-21 | E18: =BC18 -> 3.041e-19 | F18: =BD18 -> 9.908e-18 | G18: =BE18 -> 9.45e-17 | H18: =BF18 -> 5.07e-16 | I18: =BG18 -> 3.12e-15 | ... O18: =BM18 -> 1.448e-12 | P18: Fresco-II | R18: =VLOOKUP(A18,衰变常数!$A$1:$H$3800,7,FALSE) -> 1.587678e-07 | AY18: Sr-89 | AZ18: 4.167e-21 | BA18: 4.167e-21 | BB18: 4.167e-21 | BC18: 3.041e-19 | BD18: 9.908e-18 | BE18: 9.45e-17 | BF18: 5.07e-16 | BG18: 3.12e-15 | BH18: 1.58e-14 | BI18: 8.74e-14 | BJ18: 2.35e-13 | BK18: 1.04e-12 | BL18: 1.36e-12 | BM18: 1.448e-12
A19: Sr-90 | B19: =AZ19 -> 4.167e-21 | C19: =BA19 -> 4.167e-21 | D19: =BB19 -> 4.167e-21 | E19: =BC19 -> 3.037e-19 | F19: =BD19 -> 9.496e-18 | G19: =BE19 -> 9.06e-17 | H19: =BF19 -> 4.86e-16 | I19: =BG19 -> 3e-15 | ... O19: =BM19 -> 1.482e-12 | P19: Fresco-II | R19: =VLOOKUP(A19,衰变常数!$A$1:$H$3800,7,FALSE) -> 7.6292146e-10 | AY19: Sr-90 | AZ19: 4.167e-21 | BA19: 4.167e-21 | BB19: 4.167e-21 | BC19: 3.037e-19 | BD19: 9.496e-18 | BE19: 9.06e-17 | BF19: 4.86e-16 | BG19: 3e-15 | BH19: 1.52e-14 | BI19: 8.45e-14 | BJ19: 2.3e-13 | BK19: 1.04e-12 | BL19: 1.38e-12 | BM19: 1.482e-12
A20: Cs-134 | B20: =AZ20 -> 3.321e-16 | C20: =BA20 -> 3.321e-16 | D20: =BB20 -> 3.321e-16 | E20: =BC20 -> 1.455e-15 | F20: =BD20 -> 3.91e-14 | G20: =BE20 -> 1.39e-13 | H20: =BF20 -> 4.17e-13 | I20: =BG20 -> 1.11e-12 | ... O20: =BM20 -> 4.566e-09 | P20: Fresco-II | R20: =VLOOKUP(A20,衰变常数!$A$1:$H$3800,7,FALSE) -> 1.0635535e-08 | AY20: Cs-134 | AZ20: 3.321e-16 | BA20: 3.321e-16 | BB20: 3.321e-16 | BC20: 1.455e-15 | BD20: 3.91e-14 | BE20: 1.39e-13 | BF20: 4.17e-13 | BG20: 1.11e-12 | BH20: 2.85e-12 | BI20: 9.77e-12 | BJ20: 3.05e-11 | BK20: 8.37e-10 | BL20: 3.42e-09 | BM20: 4.566e-09
A21: Cs-137 | B21: =AZ21 -> 2.948e-16 | C21: =BA21 -> 2.948e-16 | D21: =BB21 -> 2.948e-16 | E21: =BC21 -> 1.273e-15 | F21: =BD21 -> 4.496e-14 | G21: =BE21 -> 1.59e-13 | H21: =BF21 -> 4.17e-13 | I21: =BG21 -> 1.3e-12 | ... O21: =BM21 -> 4.563e-09 | P21: Fresco-II | R21: =VLOOKUP(A21,衰变常数!$A$1:$H$3800,7,FALSE) -> 7.3020309e-10 | AY21: Cs-137 | AZ21: 2.948e-16 | BA21: 2.948e-16 | BB21: 2.948e-16 | BC21: 1.273e-15 | BD21: 4.496e-14 | BE21: 1.59e-13 | BF21: 4.17e-13 | BG21: 1.3e-12 | BH21: 3.33e-12 | BI21: 1.13e-11 | BJ21: 3.4e-11 | BK21: 8.63e-10 | BL21: 3.44e-09 | BM21: 4.563e-09
A22: Ag-110m | B22: =AZ22 -> 1.39e-15 | C22: =BA22 -> 1.39e-15 | D22: =BB22 -> 1.39e-15 | E22: =BC22 -> 2.254e-13 | F22: =BD22 -> 1.923e-12 | G22: =BE22 -> 1.27e-11 | H22: =BF22 -> 5.28e-11 | I22: =BG22 -> 2.34e-10 | ... O22: =BM22 -> 4.89e-07 | P22: Fresco-II | R22: =VLOOKUP(A22,衰变常数!$A$1:$H$3800,7,FALSE) -> 3.2120989e-08 | AY22: Ag-110m | AZ22: 1.39e-15 | BA22: 1.39e-15 | BB22: 1.39e-15 | BC22: 2.254e-13 | BD22: 1.923e-12 | BE22: 1.27e-11 | BF22: 5.28e-11 | BG22: 2.34e-10 | BH22: 1.18e-09 | BI22: 4.08e-09 | BJ22: 5.9e-09 | BK22: 8.01e-09 | BL22: 5.84e-08 | BM22: 4.89e-07
A23: H-3 | B23: 0 | C23: 0 | D23: 0 | E23: 0 | F23: 0 | G23: 0 | H23: 0 | I23: 0 | J23: 0 | K23: 0 | L23: 0 | M23: 0 | N23: 0 | O23: 0 | R23: =VLOOKUP(A23,衰变常数!$A$1:$H$3800,7,FALSE) -> 1.7828336e-09
A24: C-14 | B24: 0 | C24: 0 | D24: 0 | E24: 0 | F24: 0 | G24: 0 | H24: 0 | I24: 0 | J24: 0 | K24: 0 | L24: 0 | M24: 0 | N24: 0 | O24: 0 | R24: =VLOOKUP(A24,衰变常数!$A$1:$H$3800,7,FALSE) -> 3.8534294e-12
A25: Co-60 | B25: 0 | C25: 0 | D25: 0 | E25: 0 | F25: 0 | G25: 0 | H25: 0 | I25: 0 | J25: 0 | K25: 0 | L25: 0 | M25: 0 | N25: 0 | O25: 0 | R25: =VLOOKUP(A25,衰变常数!$A$1:$H$3800,7,FALSE) -> 4.1669453e-09
A26: Ar-41 | B26: 0 | C26: 0 | D26: 0 | E26: 0 | F26: 0 | G26: 0 | H26: 0 | I26: 0 | J26: 0 | K26: 0 | L26: 0 | M26: 0 | N26: 0 | O26: 0 | R26: =VLOOKUP(A26,衰变常数!$A$1:$H$3800,7,FALSE) -> 0.00010539598

Sheet DN65-事故进程
A1: 事故进程数据(堆芯温度）-郑艳华 | K1: 插值-获取体积均匀位置-径向 | N1: N_A | O1: 20 | X1: 统计温度份额
A2: DN65-FESTSTOFF TEMP-zhengyanhua-20231218 | N2: N_R | O2: 10 | AG2: PM数据
A3: 0h | X3: 温度/C | Y3: =A3 -> 0h | Z3: =A26 -> 2h | AA3: =A49 -> 8h | AB3: =A72 -> 24h | AC3: =A95 -> 48h | AD3: =A118 -> 72h | AE3: =A141 -> 96h | AG3: 温度,C | AH3: DN65,8h | AI3: DN65,24h | AJ3: dn65,48h | AK3: dn65,72h
A4: R/Z[cm] | B4: 17.68 | C4: 31.58 | D4: 54.25 | E4: 82.31 | F4: 106.26 | G4: 125.73 | H4: 142.56 | I4: 150.78 | K4: =A4 -> R/Z[cm] | L4: 0 | M4: =SQRT(L4*L4+150*150/10) -> 47.434165 | N4: =SQRT(M4*M4+150*150/10) -> 67.082039 | O4: =SQRT(N4*N4+150*150/10) -> 82.158384 | P4: =SQRT(O4*O4+150*150/10) -> 94.86833 | Q4: =SQRT(P4*P4+150*150/10) -> 106.06602 | R4: =SQRT(Q4*Q4+150*150/10) -> 116.1895 | S4: =SQRT(R4*R4+150*150/10) -> 125.499 | T4: =SQRT(S4*S4+150*150/10) -> 134.16408 | ... V4: =SQRT(U4*U4+150*150/10) -> 150 | X4: 0
A5: 27.5 | B5: 280.89 | C5: 280.56 | D5: 279.65 | E5: 278.05 | F5: 276.31 | G5: 274.93 | H5: 274.66 | I5: 270.37 | K5: =A5 -> 27.5 | L5: =TREND(B5:C5,B$4:C$4,L$4) -> 281.30974 | M5: =TREND(C5:D5,C$4:D$4,M$4) -> 279.9236 | N5: =TREND(D5:E5,D$4:E$4,N$4) -> 278.91831 | O5: =TREND(D5:E5,D$4:E$4,O$4) -> 278.05865 | P5: =TREND(E5:F5,E$4:F$4,P$4) -> 277.13762 | Q5: =TREND(E5:F5,E$4:F$4,Q$4) -> 276.32409 | R5: =TREND(F5:G5,F$4:G$4,R$4) -> 275.60621 | S5: =TREND(F5:G5,F$4:G$4,S$4) -> 274.94637 | T5: =TREND(G5:H5,G$4:H$4,T$4) -> 274.79469 | U5: =TREND(G5:H5,G$4:H$4,U$4) -> 274.66413 | V5: =TREND(H5:I5,H$4:I$4,V$4) -> 270.77708 | X5: 400 | Y5: =COUNTIFS(OFFSET($L$5,0,0,$O$1,$O$2),"<="&($X5),OFFSET($L$5,0,0,$O$1,$O$2),">"&($X4))/$O$1/$O$2 -> 0.225 | Z5: =COUNTIFS(OFFSET($L$28,0,0,$O$1,$O$2),"<="&($X5),OFFSET($L$28,0,0,$O$1,$O$2),">"&($X4))/$O$1/$O$2 -> 0.07 | AA5: =COUNTIFS(OFFSET($L$51,0,0,$O$1,$O$2),"<="&($X5),OFFSET($L$51,0,0,$O$1,$O$2),">"&($X4))/$O$1/$O$2 -> 0.01 | AB5: =COUNTIFS(OFFSET($L$74,0,0,$O$1,$O$2),"<="&($X5),OFFSET($L$74,0,0,$O$1,$O$2),">"&($X4))/$O$1/$O$2 -> 0.005 | AC5: =COUNTIFS(OFFSET($L$97,0,0,$O$1,$O$2),"<="&($X5),OFFSET($L$97,0,0,$O$1,$O$2),">"&($X4))/$O$1/$O$2 -> 0 | AD5: =COUNTIFS(OFFSET($L$120,0,0,$O$1,$O$2),"<="&($X5),OFFSET($L$120,0,0,$O$1,$O$2),">"&($X4))/$O$1/$O$2 -> 0 | AE5: =COUNTIFS(OFFSET($L$143,0,0,$O$1,$O$2),"<="&($X5),OFFSET($L$143,0,0,$O$1,$O$2),">"&($X4))/$O$1/$O$2 -> 0 | AG5: 400
A6: 82.5 | B6: 310.73 | C6: 309.79 | D6: 307.32 | E6: 302.79 | F6: 297.88 | G6: 294.08 | H6: 292.75 | I6: 283.93 | K6: =A6 -> 82.5 | L6: =TREND(B6:C6,B$4:C$4,L$4) -> 311.92563 | M6: =TREND(C6:D6,C$4:D$4,M$4) -> 308.06262 | N6: =TREND(D6:E6,D$4:E$4,N$4) -> 305.2484 | O6: =TREND(D6:E6,D$4:E$4,O$4) -> 302.81448 | P6: =TREND(E6:F6,E$4:F$4,P$4) -> 300.21541 | Q6: =TREND(E6:F6,E$4:F$4,Q$4) -> 297.91977 | R6: =TREND(F6:G6,F$4:G$4,R$4) -> 295.94204 | S6: =TREND(F6:G6,F$4:G$4,S$4) -> 294.12508 | T6: =TREND(G6:H6,G$4:H$4,T$4) -> 293.41349 | U6: =TREND(G6:H6,G$4:H$4,U$4) -> 292.77035 | V6: =TREND(H6:I6,H$4:I$4,V$4) -> 284.76693 | X6: 500 | Y6: =COUNTIFS(OFFSET($L$5,0,0,$O$1,$O$2),"<="&($X6),OFFSET($L$5,0,0,$O$1,$O$2),">"&($X5))/$O$1/$O$2 -> 0.095 | Z6: =COUNTIFS(OFFSET($L$28,0,0,$O$1,$O$2),"<="&($X6),OFFSET($L$28,0,0,$O$1,$O$2),">"&($X5))/$O$1/$O$2 -> 0.075 | AA6: =COUNTIFS(OFFSET($L$51,0,0,$O$1,$O$2),"<="&($X6),OFFSET($L$51,0,0,$O$1,$O$2),">"&($X5))/$O$1/$O$2 -> 0.045 | AB6: =COUNTIFS(OFFSET($L$74,0,0,$O$1,$O$2),"<="&($X6),OFFSET($L$74,0,0,$O$1,$O$2),">"&($X5))/$O$1/$O$2 -> 0.025 | AC6: =COUNTIFS(OFFSET($L$97,0,0,$O$1,$O$2),"<="&($X6),OFFSET($L$97,0,0,$O$1,$O$2),">"&($X5))/$O$1/$O$2 -> 0.01 | AD6: =COUNTIFS(OFFSET($L$120,0,0,$O$1,$O$2),"<="&($X6),OFFSET($L$120,0,0,$O$1,$O$2),">"&($X5))/$O$1/$O$2 -> 0.01 | AE6: =COUNTIFS(OFFSET($L$143,0,0,$O$1,$O$2),"<="&($X6),OFFSET($L$143,0,0,$O$1,$O$2),">"&($X5))/$O$1/$O$2 -> 0.01 | AG6: 500
A7: 137.5 | B7: 349.36 | C7: 347.62 | D7: 343.16 | E7: 335.01 | F7: 326.28 | G7: 319.56 | H7: 316.87 | I7: 304.88 | K7: =A7 -> 137.5 | L7: =TREND(B7:C7,B$4:C$4,L$4) -> 351.57318 | M7: =TREND(C7:D7,C$4:D$4,M$4) -> 344.50092 | N7: =TREND(D7:E7,D$4:E$4,N$4) -> 339.43295 | O7: =TREND(D7:E7,D$4:E$4,O$4) -> 335.05404 | P7: =TREND(E7:F7,E$4:F$4,P$4) -> 330.43237 | Q7: =TREND(E7:F7,E$4:F$4,Q$4) -> 326.35071 | R7: =TREND(F7:G7,F$4:G$4,R$4) -> 322.85287 | S7: =TREND(F7:G7,F$4:G$4,S$4) -> 319.63973 | T7: =TREND(G7:H7,G$4:H$4,T$4) -> 318.21195 | U7: =TREND(G7:H7,G$4:H$4,U$4) -> 316.91116 | V7: =TREND(H7:I7,H$4:I$4,V$4) -> 306.01774 | X7: 600 | Y7: =COUNTIFS(OFFSET($L$5,0,0,$O$1,$O$2),"<="&($X7),OFFSET($L$5,0,0,$O$1,$O$2),">"&($X6))/$O$1/$O$2 -> 0.1 | Z7: =COUNTIFS(OFFSET($L$28,0,0,$O$1,$O$2),"<="&($X7),OFFSET($L$28,0,0,$O$1,$O$2),">"&($X6))/$O$1/$O$2 -> 0.085 | AA7: =COUNTIFS(OFFSET($L$51,0,0,$O$1,$O$2),"<="&($X7),OFFSET($L$51,0,0,$O$1,$O$2),">"&($X6))/$O$1/$O$2 -> 0.055 | AB7: =COUNTIFS(OFFSET($L$74,0,0,$O$1,$O$2),"<="&($X7),OFFSET($L$74,0,0,$O$1,$O$2),">"&($X6))/$O$1/$O$2 -> 0.075 | AC7: =COUNTIFS(OFFSET($L$97,0,0,$O$1,$O$2),"<="&($X7),OFFSET($L$97,0,0,$O$1,$O$2),">"&($X6))/$O$1/$O$2 -> 0.06 | AD7: =COUNTIFS(OFFSET($L$120,0,0,$O$1,$O$2),"<="&($X7),OFFSET($L$120,0,0,$O$1,$O$2),">"&($X6))/$O$1/$O$2 -> 0.06 | AE7: =COUNTIFS(OFFSET($L$143,0,0,$O$1,$O$2),"<="&($X7),OFFSET($L$143,0,0,$O$1,$O$2),">"&($X6))/$O$1/$O$2 -> 0.07 | AG7: 600 | AH7: 0.2366 | AI7: 0.1263 | AJ7: 0.1156 | AK7: 0.1156
A8: 192.5 | B8: 395.14 | C8: 392.45 | D8: 385.74 | E8: 373.61 | F8: 360.68 | G8: 350.76 | H8: 346.58 | I8: 330.95 | K8: =A8 -> 192.5 | L8: =TREND(B8:C8,B$4:C$4,L$4) -> 398.56153 | M8: =TREND(C8:D8,C$4:D$4,M$4) -> 387.75739 | N8: =TREND(D8:E8,D$4:E$4,N$4) -> 380.19286 | O8: =TREND(D8:E8,D$4:E$4,O$4) -> 373.67554 | P8: =TREND(E8:F8,E$4:F$4,P$4) -> 366.83007 | Q8: =TREND(E8:F8,E$4:F$4,Q$4) -> 360.78473 | R8: =TREND(F8:G8,F$4:G$4,R$4) -> 355.6209 | S8: =TREND(F8:G8,F$4:G$4,S$4) -> 350.87769 | T8: =TREND(G8:H8,G$4:H$4,T$4) -> 348.66526 | U8: =TREND(G8:H8,G$4:H$4,U$4) -> 346.64396 | V8: =TREND(H8:I8,H$4:I$4,V$4) -> 332.43314 | X8: 700 | Y8: =COUNTIFS(OFFSET($L$5,0,0,$O$1,$O$2),"<="&($X8),OFFSET($L$5,0,0,$O$1,$O$2),">"&($X7))/$O$1/$O$2 -> 0.135 | Z8: =COUNTIFS(OFFSET($L$28,0,0,$O$1,$O$2),"<="&($X8),OFFSET($L$28,0,0,$O$1,$O$2),">"&($X7))/$O$1/$O$2 -> 0.13 | AA8: =COUNTIFS(OFFSET($L$51,0,0,$O$1,$O$2),"<="&($X8),OFFSET($L$51,0,0,$O$1,$O$2),">"&($X7))/$O$1/$O$2 -> 0.095 | AB8: =COUNTIFS(OFFSET($L$74,0,0,$O$1,$O$2),"<="&($X8),OFFSET($L$74,0,0,$O$1,$O$2),">"&($X7))/$O$1/$O$2 -> 0.075 | AC8: =COUNTIFS(OFFSET($L$97,0,0,$O$1,$O$2),"<="&($X8),OFFSET($L$97,0,0,$O$1,$O$2),">"&($X7))/$O$1/$O$2 -> 0.075 | AD8: =COUNTIFS(OFFSET($L$120,0,0,$O$1,$O$2),"<="&($X8),OFFSET($L$120,0,0,$O$1,$O$2),">"&($X7))/$O$1/$O$2 -> 0.085 | AE8: =COUNTIFS(OFFSET($L$143,0,0,$O$1,$O$2),"<="&($X8),OFFSET($L$143,0,0,$O$1,$O$2),">"&($X7))/$O$1/$O$2 -> 0.085 | AG8: 700 | AH8: 0.1616 | AI8: 0.1121 | AJ8: 0.0832 | AK8: 0.0878
A9: 241.5 | B9: 440.29 | C9: 436.65 | D9: 427.88 | E9: 412.28 | F9: 395.78 | G9: 383.35 | H9: 378.2 | I9: 358.93 | K9: =A9 -> 241.5 | L9: =TREND(B9:C9,B$4:C$4,L$4) -> 444.91987 | M9: =TREND(C9:D9,C$4:D$4,M$4) -> 430.51674 | N9: =TREND(D9:E9,D$4:E$4,N$4) -> 420.74601 | O9: =TREND(D9:E9,D$4:E$4,O$4) -> 412.36429 | P9: =TREND(E9:F9,E$4:F$4,P$4) -> 403.62812 | Q9: =TREND(E9:F9,E$4:F$4,Q$4) -> 395.91364 | R9: =TREND(F9:G9,F$4:G$4,R$4) -> 389.44083 | S9: =TREND(F9:G9,F$4:G$4,S$4) -> 383.49747 | T9: =TREND(G9:H9,G$4:H$4,T$4) -> 380.76916 | U9: =TREND(G9:H9,G$4:H$4,U$4) -> 378.2788 | V9: =TREND(H9:I9,H$4:I$4,V$4) -> 360.75854 | X9: 800 | Y9: =COUNTIFS(OFFSET($L$5,0,0,$O$1,$O$2),"<="&($X9),OFFSET($L$5,0,0,$O$1,$O$2),">"&($X8))/$O$1/$O$2 -> 0.205 | Z9: =COUNTIFS(OFFSET($L$28,0,0,$O$1,$O$2),"<="&($X9),OFFSET($L$28,0,0,$O$1,$O$2),">"&($X8))/$O$1/$O$2 -> 0.13 | AA9: =COUNTIFS(OFFSET($L$51,0,0,$O$1,$O$2),"<="&($X9),OFFSET($L$51,0,0,$O$1,$O$2),">"&($X8))/$O$1/$O$2 -> 0.145 | AB9: =COUNTIFS(OFFSET($L$74,0,0,$O$1,$O$2),"<="&($X9),OFFSET($L$74,0,0,$O$1,$O$2),">"&($X8))/$O$1/$O$2 -> 0.12 | AC9: =COUNTIFS(OFFSET($L$97,0,0,$O$1,$O$2),"<="&($X9),OFFSET($L$97,0,0,$O$1,$O$2),">"&($X8))/$O$1/$O$2 -> 0.075 | AD9: =COUNTIFS(OFFSET($L$120,0,0,$O$1,$O$2),"<="&($X9),OFFSET($L$120,0,0,$O$1,$O$2),">"&($X8))/$O$1/$O$2 -> 0.075 | AE9: =COUNTIFS(OFFSET($L$143,0,0,$O$1,$O$2),"<="&($X9),OFFSET($L$143,0,0,$O$1,$O$2),">"&($X8))/$O$1/$O$2 -> 0.095 | AG9: 800 | AH9: 0.134 | AI9: 0.163 | AJ9: 0.1064 | AK9: 0.1102
A10: 296.5 | B10: 499.84 | C10: 495.05 | D10: 483.75 | E10: 464.01 | F10: 443.62 | G10: 429.12 | H10: 423.34 | I10: 391.86 | K10: =A10 -> 296.5 | L10: =TREND(B10:C10,B$4:C$4,L$4) -> 505.9326 | M10: =TREND(C10:D10,C$4:D$4,M$4) -> 487.14739 | N10: =TREND(D10:E10,D$4:E$4,N$4) -> 474.72276 | O10: =TREND(D10:E10,D$4:E$4,O$4) -> 464.11666 | P10: =TREND(E10:F10,E$4:F$4,P$4) -> 453.31838 | Q10: =TREND(E10:F10,E$4:F$4,Q$4) -> 443.78515 | R10: =TREND(F10:G10,F$4:G$4,R$4) -> 436.22515 | S10: =TREND(F10:G10,F$4:G$4,S$4) -> 429.29203 | T10: =TREND(G10:H10,G$4:H$4,T$4) -> 426.22345 | U10: =TREND(G10:H10,G$4:H$4,U$4) -> 423.42844 | V10: =TREND(H10:I10,H$4:I$4,V$4) -> 394.84715 | X10: 900 | Y10: =COUNTIFS(OFFSET($L$5,0,0,$O$1,$O$2),"<="&($X10),OFFSET($L$5,0,0,$O$1,$O$2),">"&($X9))/$O$1/$O$2 -> 0.18 | Z10: =COUNTIFS(OFFSET($L$28,0,0,$O$1,$O$2),"<="&($X10),OFFSET($L$28,0,0,$O$1,$O$2),">"&($X9))/$O$1/$O$2 -> 0.17 | AA10: =COUNTIFS(OFFSET($L$51,0,0,$O$1,$O$2),"<="&($X10),OFFSET($L$51,0,0,$O$1,$O$2),">"&($X9))/$O$1/$O$2 -> 0.14 | AB10: =COUNTIFS(OFFSET($L$74,0,0,$O$1,$O$2),"<="&($X10),OFFSET($L$74,0,0,$O$1,$O$2),">"&($X9))/$O$1/$O$2 -> 0.14 | AC10: =COUNTIFS(OFFSET($L$97,0,0,$O$1,$O$2),"<="&($X10),OFFSET($L$97,0,0,$O$1,$O$2),">"&($X9))/$O$1/$O$2 -> 0.11 | AD10: =COUNTIFS(OFFSET($L$120,0,0,$O$1,$O$2),"<="&($X10),OFFSET($L$120,0,0,$O$1,$O$2),">"&($X9))/$O$1/$O$2 -> 0.115 | AE10: =COUNTIFS(OFFSET($L$143,0,0,$O$1,$O$2),"<="&($X10),OFFSET($L$143,0,0,$O$1,$O$2),">"&($X9))/$O$1/$O$2 -> 0.105 | AG10: 900 | AH10: 0.1599 | AI10: 0.1408 | AJ10: 0.1704 | AK10: 0.1573
